Workbook

Sheet Raw data
A1: Iteration | B1: Project | C1: ECN | D1: ECN release | E1: Part number | F1: Complexity | G1: EAU | H1: Delivery profile | I1: Quotation profile | J1: Price profile | K1: Punctuality profile | L1: Supplier ID | M1: Supplier name | N1: Price | O1: Lead time | P1: RFQ date | Q1: Quotation date | R1: REQ date | S1: PO date | T1: ETA | U1: Delivery date | V1: ISIR documents | W1: ISIR approval | X1: PPAP approval | Y1: Contract date | Z1: Quotation time | AA1: OTD | AB1: Delivery time | AC1: FY Spend | AD1: Awarded | AE1: MCS ready | AF1: Pilot ready | AG1: SOP ready | AH1: Unnamed: 0
A2: 2 | B2: Juneau | C2: ECN0000301 | D2: 45483 | E2: A0A000001 | F2: medium | G2: 224 | H2: regular | I2: low | J2: regular | K2: high | L2: 10000033 | M2: Tuberías ABC, S.A. de C.V. | N2: 29.46 | O2: 30 | P2: 45489 | Q2: 45531 | R2: 45531 | S2: 45542 | T2: 45572 | U2: 45572 | V2: 45572 | W2: 45604 | X2: 45611 | Y2: 45612 | Z2: 42 | AA2: TRUE | AB2: 30 | AC2: 6599.04 | AD2: TRUE | AE2: FALSE | AF2: FALSE | AG2: FALSE
A3: 2 | B3: Juneau | C3: ECN0000301 | D3: 45483 | E3: A0D000001 | F3: medium | G3: 224 | H3: regular | I3: low | J3: regular | K3: high | L3: 10000033 | M3: Tuberías ABC, S.A. de C.V. | N3: 24.09 | O3: 30 | P3: 45489 | Q3: 45531 | R3: 45531 | S3: 45542 | T3: 45572 | U3: 45572 | V3: 45572 | W3: 45604 | X3: 45611 | Y3: 45612 | Z3: 42 | AA3: TRUE | AB3: 30 | AC3: 5396.16 | AD3: TRUE | AE3: FALSE | AF3: FALSE | AG3: FALSE
A4: 2 | B4: Juneau | C4: ECN0000301 | D4: 45483 | E4: A0A000001 | F4: medium | G4: 224 | H4: regular | I4: high | J4: low | K4: regular | L4: 10000047 | M4: Tuberías DEF, S. de R.L. | N4: 74.36 | O4: 14 | P4: 45483 | Q4: 45528 | Z4: 45 | AC4: 16656.64 | AD4: 0
A5: 2 | B5: Juneau | C5: ECN0000301 | D5: 45483 | E5: A0D000001 | F5: medium | G5: 224 | H5: regular | I5: high | J5: low | K5: regular | L5: 10000047 | M5: Tuberías DEF, S. de R.L. | N5: 13.35 | O5: 14 | P5: 45483 | Q5: 45528 | Z5: 45 | AC5: 2990.4 | AD5: 0
A6: 2 | B6: Juneau | C6: ECN0000301 | D6: 45483 | E6: A0A000001 | F6: medium | G6: 224 | H6: high | I6: high | J6: low | K6: low | L6: 10000073 | M6: Tuberías GHI, S.A.S. | N6: 75.17 | O6: 28 | P6: 45489 | Q6: 45543 | Z6: 54 | AC6: 16838.08 | AD6: 0
A7: 2 | B7: Juneau | C7: ECN0000301 | D7: 45483 | E7: A0D000001 | F7: medium | G7: 224 | H7: high | I7: high | J7: low | K7: low | L7: 10000073 | M7: Tuberías GHI, S.A.S. | N7: 1.64 | O7: 28 | P7: 45489 | Q7: 45543 | Z7: 54 | AC7: 367.36 | AD7: 0
A8: 2 | B8: Juneau | C8: ECN0000301 | D8: 45483 | E8: A0A000001 | F8: medium | G8: 224 | H8: low | I8: low | J8: low | K8: high | L8: 10000082 | M8: Tuberías Súper, S.A.P.I. | N8: 35.14 | P8: 45483 | Q8: 45527 | Z8: 44 | AC8: 7871.36 | AD8: 0
A9: 2 | B9: Juneau | C9: ECN0000301 | D9: 45483 | E9: A0D000001 | F9: medium | G9: 224 | H9: low | I9: low | J9: low | K9: high | L9: 10000082 | M9: Tuberías Súper, S.A.P.I. | N9: 6.01 | P9: 45483 | Q9: 45527 | Z9: 44 | AC9: 1346.24 | AD9: 0
A10: 2 | B10: Juneau | C10: ECN0000302 | D10: 45490 | E10: A0A000002 | F10: medium | G10: 23 | H10: regular | I10: low | J10: regular | K10: high | L10: 10000033 | M10: Tuberías ABC, S.A. de C.V. | N10: 81.77 | O10: 30 | P10: 45490 | Q10: 45497 | R10: 45507 | S10: 45517 | T10: 45560 | U10: 45558 | V10: 45558 | W10: 45615 | X10: 45615 | Y10: 45621 | Z10: 7.2 | AA10: TRUE | AB10: 41 | AC10: 1880.71 | AD10: TRUE | AE10: FALSE | AF10: FALSE | AG10: FALSE
A11: 2 | B11: Juneau | C11: ECN0000302 | D11: 45490 | E11: A0A000003 | F11: low | G11: 23 | H11: regular | I11: low | J11: regular | K11: high | L11: 10000033 | M11: Tuberías ABC, S.A. de C.V. | N11: 28.61 | O11: 30 | P11: 45490 | Q11: 45497 | R11: 45507 | S11: 45517 | T11: 45560 | U11: 45558 | V11: 45558 | W11: 45615 | X11: 45615 | Y11: 45621 | Z11: 7.2 | AA11: TRUE | AB11: 41 | AC11: 658.03 | AD11: TRUE | AE11: FALSE | AF11: FALSE | AG11: FALSE
A12: 2 | B12: Juneau | C12: ECN0000302 | D12: 45490 | E12: A0A000004 | F12: low | G12: 23 | H12: regular | I12: low | J12: regular | K12: high | L12: 10000033 | M12: Tuberías ABC, S.A. de C.V. | N12: 35.71 | O12: 30 | P12: 45490 | Q12: 45497 | R12: 45507 | S12: 45517 | T12: 45560 | U12: 45558 | V12: 45558 | W12: 45615 | X12: 45615 | Y12: 45621 | Z12: 7.2 | AA12: TRUE | AB12: 41 | AC12: 821.33 | AD12: TRUE | AE12: FALSE | AF12: FALSE | AG12: FALSE
A13: 2 | B13: Juneau | C13: ECN0000302 | D13: 45490 | E13: A0A000005 | F13: low | G13: 23 | H13: regular | I13: low | J13: regular | K13: high | L13: 10000033 | M13: Tuberías ABC, S.A. de C.V. | N13: 14.9 | O13: 30 | P13: 45490 | Q13: 45497 | R13: 45507 | S13: 45517 | T13: 45560 | U13: 45558 | V13: 45558 | W13: 45615 | X13: 45615 | Y13: 45621 | Z13: 7.2 | AA13: TRUE | AB13: 41 | AC13: 342.7 | AD13: TRUE | AE13: FALSE | AF13: FALSE | AG13: FALSE
A14: 2 | B14: Juneau | C14: ECN0000302 | D14: 45490 | E14: A0A000002 | F14: medium | G14: 23 | H14: regular | I14: high | J14: low | K14: regular | L14: 10000047 | M14: Tuberías DEF, S. de R.L. | N14: 77.11 | O14: 14 | P14: 45496 | Q14: 45560 | Z14: 64 | AC14: 1773.53 | AD14: 0
A15: 2 | B15: Juneau | C15: ECN0000302 | D15: 45490 | E15: A0A000003 | F15: low | G15: 23 | H15: regular | I15: high | J15: low | K15: regular | L15: 10000047 | M15: Tuberías DEF, S. de R.L. | N15: 22.98 | O15: 14 | P15: 45496 | Q15: 45560 | Z15: 64 | AC15: 528.54 | AD15: 0
A16: 2 | B16: Juneau | C16: ECN0000302 | D16: 45490 | E16: A0A000004 | F16: low | G16: 23 | H16: regular | I16: high | J16: low | K16: regular | L16: 10000047 | M16: Tuberías DEF, S. de R.L. | N16: 11.42 | O16: 14 | P16: 45496 | Q16: 45560 | Z16: 64 | AC16: 262.66 | AD16: 0
A17: 2 | B17: Juneau | C17: ECN0000302 | D17: 45490 | E17: A0A000005 | F17: low | G17: 23 | H17: regular | I17: high | J17: low | K17: regular | L17: 10000047 | M17: Tuberías DEF, S. de R.L. | N17: 14.89 | O17: 14 | P17: 45496 | Q17: 45560 | Z17: 64 | AC17: 342.47 | AD17: 0
A18: 2 | B18: Juneau | C18: ECN0000302 | D18: 45490 | E18: A0A000002 | F18: medium | G18: 23 | H18: high | I18: high | J18: low | K18: low | L18: 10000073 | M18: Tuberías GHI, S.A.S. | N18: 58.48 | O18: 28 | P18: 45490 | Q18: 45526 | Z18: 36 | AC18: 1345.04 | AD18: 0
A19: 2 | B19: Juneau | C19: ECN0000302 | D19: 45490 | E19: A0A000003 | F19: low | G19: 23 | H19: high | I19: high | J19: low | K19: low | L19: 10000073 | M19: Tuberías GHI, S.A.S. | N19: 13.58 | O19: 28 | P19: 45490 | Q19: 45526 | Z19: 36 | AC19: 312.34 | AD19: 0
A20: 2 | B20: Juneau | C20: ECN0000302 | D20: 45490 | E20: A0A000004 | F20: low | G20: 23 | H20: high | I20: high | J20: low | K20: low | L20: 10000073 | M20: Tuberías GHI, S.A.S. | N20: 23.39 | O20: 28 | P20: 45490 | Q20: 45526 | Z20: 36 | AC20: 537.97 | AD20: 0
A21: 2 | B21: Juneau | C21: ECN0000302 | D21: 45490 | E21: A0A000005 | F21: low | G21: 23 | H21: high | I21: high | J21: low | K21: low | L21: 10000073 | M21: Tuberías GHI, S.A.S. | N21: 21.14 | O21: 28 | P21: 45490 | Q21: 45526 | Z21: 36 | AC21: 486.22 | AD21: 0
A22: 2 | B22: Juneau | C22: ECN0000302 | D22: 45490 | E22: A0A000002 | F22: medium | G22: 23 | H22: low | I22: low | J22: low | K22: high | L22: 10000082 | M22: Tuberías Súper, S.A.P.I. | N22: 54.49 | P22: 45494 | Q22: 45512 | Z22: 18 | AC22: 1253.27 | AD22: 0
A23: 2 | B23: Juneau | C23: ECN0000302 | D23: 45490 | E23: A0A000003 | F23: low | G23: 23 | H23: low | I23: low | J23: low | K23: high | L23: 10000082 | M23: Tuberías Súper, S.A.P.I. | N23: 15.92 | P23: 45494 | Q23: 45512 | Z23: 18 | AC23: 366.16 | AD23: 0
A24: 2 | B24: Juneau | C24: ECN0000302 | D24: 45490 | E24: A0A000004 | F24: low | G24: 23 | H24: low | I24: low | J24: low | K24: high | L24: 10000082 | M24: Tuberías Súper, S.A.P.I. | N24: 18.29 | P24: 45494 | Q24: 45512 | Z24: 18 | AC24: 420.67 | AD24: 0
A25: 2 | B25: Juneau | C25: ECN0000302 | D25: 45490 | E25: A0A000005 | F25: low | G25: 23 | H25: low | I25: low | J25: low | K25: high | L25: 10000082 | M25: Tuberías Súper, S.A.P.I. | N25: 20.63 | P25: 45494 | Q25: 45512 | Z25: 18 | AC25: 474.49 | AD25: 0
A26: 2 | B26: Juneau | C26: ECN0000303 | D26: 45493 | E26: A0A000006 | F26: medium | G26: 295 | H26: regular | I26: low | J26: regular | K26: high | L26: 10000033 | M26: Tuberías ABC, S.A. de C.V. | N26: 107 | O26: 30 | P26: 45499 | Q26: 45508 | R26: 45508 | S26: 45515 | T26: 45540 | U26: 45539 | V26: 45539 | W26: 45588 | X26: 45588 | Y26: 45594 | Z26: 9 | AA26: TRUE | AB26: 24 | AC26: 31565 | AD26: TRUE | AE26: FALSE | AF26: FALSE | AG26: FALSE
A27: 2 | B27: Juneau | C27: ECN0000303 | D27: 45493 | E27: A0A000007 | F27: low | G27: 295 | H27: regular | I27: low | J27: regular | K27: high | L27: 10000033 | M27: Tuberías ABC, S.A. de C.V. | N27: 22.2 | O27: 30 | P27: 45499 | Q27: 45508 | R27: 45508 | S27: 45515 | T27: 45540 | U27: 45539 | V27: 45539 | W27: 45588 | X27: 45588 | Y27: 45594 | Z27: 9 | AA27: TRUE | AB27: 24 | AC27: 6549 | AD27: TRUE | AE27: FALSE | AF27: FALSE | AG27: FALSE
A28: 2 | B28: Juneau | C28: ECN0000303 | D28: 45493 | E28: A0G000334 | F28: high | G28: 295 | H28: regular | I28: low | J28: regular | K28: high | L28: 10000033 | M28: Tuberías ABC, S.A. de C.V. | N28: 88.88 | O28: 30 | P28: 45499 | Q28: 45508 | R28: 45508 | S28: 45515 | T28: 45540 | U28: 45539 | V28: 45539 | W28: 45588 | X28: 45588 | Y28: 45594 | Z28: 9 | AA28: TRUE | AB28: 24 | AC28: 26219.6 | AD28: TRUE | AE28: FALSE | AF28: FALSE | AG28: FALSE
A29: 2 | B29: Juneau | C29: ECN0000303 | D29: 45493 | E29: A0A000006 | F29: medium | G29: 295 | H29: regular | I29: high | J29: low | K29: regular | L29: 10000047 | M29: Tuberías DEF, S. de R.L. | N29: 49.23 | O29: 14 | P29: 45493 | Q29: 45505 | Z29: 12 | AC29: 14522.85 | AD29: 0
A30: 2 | B30: Juneau | C30: ECN0000303 | D30: 45493 | E30: A0A000007 | F30: low | G30: 295 | H30: regular | I30: high | J30: low | K30: regular | L30: 10000047 | M30: Tuberías DEF, S. de R.L. | N30: 17.35 | O30: 14 | P30: 45493 | Q30: 45505 | Z30: 12 | AC30: 5118.25 | AD30: 0
A31: 2 | B31: Juneau | C31: ECN0000303 | D31: 45493 | E31: A0G000334 | F31: high | G31: 295 | H31: regular | I31: high | J31: low | K31: regular | L31: 10000047 | M31: Tuberías DEF, S. de R.L. | N31: 102.13 | O31: 14 | P31: 45493 | Q31: 45505 | Z31: 12 | AC31: 30128.35 | AD31: 0
A32: 2 | B32: Juneau | C32: ECN0000303 | D32: 45493 | E32: A0A000006 | F32: medium | G32: 295 | H32: high | I32: high | J32: low | K32: low | L32: 10000073 | M32: Tuberías GHI, S.A.S. | N32: 1.64 | O32: 28 | P32: 45493 | Q32: 45504 | Z32: 11.7 | AC32: 483.8 | AD32: 0
A33: 2 | B33: Juneau | C33: ECN0000303 | D33: 45493 | E33: A0A000007 | F33: low | G33: 295 | H33: high | I33: high | J33: low | K33: low | L33: 10000073 | M33: Tuberías GHI, S.A.S. | N33: 29.45 | O33: 28 | P33: 45493 | Q33: 45504 | Z33: 11.7 | AC33: 8687.75 | AD33: 0
A34: 2 | B34: Juneau | C34: ECN0000303 | D34: 45493 | E34: A0G000334 | F34: high | G34: 295 | H34: high | I34: high | J34: low | K34: low | L34: 10000073 | M34: Tuberías GHI, S.A.S. | N34: 83.93 | O34: 28 | P34: 45493 | Q34: 45504 | Z34: 11.7 | AC34: 24759.35 | AD34: 0
A35: 2 | B35: Juneau | C35: ECN0000303 | D35: 45493 | E35: A0A000006 | F35: medium | G35: 295 | H35: low | I35: low | J35: low | K35: high | L35: 10000082 | M35: Tuberías Súper, S.A.P.I. | N35: 42.76 | P35: 45498 | Q35: 45523 | Z35: 25 | AC35: 12614.2 | AD35: 0
A36: 2 | B36: Juneau | C36: ECN0000303 | D36: 45493 | E36: A0A000007 | F36: low | G36: 295 | H36: low | I36: low | J36: low | K36: high | L36: 10000082 | M36: Tuberías Súper, S.A.P.I. | N36: 20.33 | P36: 45498 | Q36: 45523 | Z36: 25 | AC36: 5997.35 | AD36: 0
A37: 2 | B37: Juneau | C37: ECN0000303 | D37: 45493 | E37: A0G000334 | F37: high | G37: 295 | H37: low | I37: low | J37: low | K37: high | L37: 10000082 | M37: Tuberías Súper, S.A.P.I. | N37: 48 | P37: 45498 | Q37: 45523 | Z37: 25 | AC37: 14160 | AD37: 0
A38: 2 | B38: Juneau | C38: ECN0000304 | D38: 45329 | E38: A0E000001 | F38: high | G38: 256 | H38: regular | I38: low | J38: regular | K38: high | L38: 10000033 | M38: Tuberías ABC, S.A. de C.V. | N38: 142.61 | O38: 30 | P38: 45330 | Q38: 45372 | R38: 45393 | S38: 45395 | T38: 45425 | U38: 45424 | V38: 45427 | W38: 45534 | X38: 45539 | Y38: 45542 | Z38: 42 | AA38: TRUE | AB38: 29 | AC38: 36508.16 | AD38: TRUE | AE38: TRUE | AF38: FALSE | AG38: TRUE
A39: 2 | B39: Juneau | C39: ECN0000304 | D39: 45329 | E39: A0E000002 | F39: high | G39: 256 | H39: regular | I39: low | J39: regular | K39: high | L39: 10000033 | M39: Tuberías ABC, S.A. de C.V. | N39: 100.69 | O39: 30 | P39: 45330 | Q39: 45372 | R39: 45393 | S39: 45395 | T39: 45425 | U39: 45424 | V39: 45427 | W39: 45534 | X39: 45539 | Y39: 45542 | Z39: 42 | AA39: TRUE | AB39: 29 | AC39: 25776.64 | AD39: TRUE | AE39: TRUE | AF39: FALSE | AG39: TRUE
A40: 2 | B40: Juneau | C40: ECN0000304 | D40: 45329 | E40: A0E000003 | F40: high | G40: 256 | H40: regular | I40: low | J40: regular | K40: high | L40: 10000033 | M40: Tuberías ABC, S.A. de C.V. | N40: 84.99 | O40: 30 | P40: 45330 | Q40: 45372 | R40: 45393 | S40: 45395 | T40: 45425 | U40: 45424 | V40: 45427 | W40: 45534 | X40: 45539 | Y40: 45542 | Z40: 42 | AA40: TRUE | AB40: 29 | AC40: 21757.44 | AD40: TRUE | AE40: TRUE | AF40: FALSE | AG40: TRUE
...

Sheet Quoted Spend
A1: Iteration | B1: Tuberías ABC, S.A. de C.V. | C1: Tuberías DEF, S. de R.L. | D1: Tuberías GHI, S.A.S. | E1: Tuberías Súper, S.A.P.I. | F1: Total
A2: 1 | B2: =SUMIFS('Raw data'!$AC$2:$AC$15201,'Raw data'!$A$2:$A$15201,'Quoted Spend'!$A2+1,'Raw data'!$M$2:$M$15201,'Quoted Spend'!B$1) -> 475060.47 | C2: =SUMIFS('Raw data'!$AC$2:$AC$15201,'Raw data'!$A$2:$A$15201,'Quoted Spend'!$A2+1,'Raw data'!$M$2:$M$15201,'Quoted Spend'!C$1) -> 384722.15 | D2: =SUMIFS('Raw data'!$AC$2:$AC$15201,'Raw data'!$A$2:$A$15201,'Quoted Spend'!$A2+1,'Raw data'!$M$2:$M$15201,'Quoted Spend'!D$1) -> 332456.91 | E2: =SUMIFS('Raw data'!$AC$2:$AC$15201,'Raw data'!$A$2:$A$15201,'Quoted Spend'!$A2+1,'Raw data'!$M$2:$M$15201,'Quoted Spend'!E$1) -> 344752.57 | F2: =AVERAGE(B2:D2) -> 397413.18
A3: =A2+1 -> 2 | B3: =SUMIFS('Raw data'!$AC$2:$AC$15201,'Raw data'!$A$2:$A$15201,'Quoted Spend'!$A3+1,'Raw data'!$M$2:$M$15201,'Quoted Spend'!B$1) -> 378461.67 | C3: =SUMIFS('Raw data'!$AC$2:$AC$15201,'Raw data'!$A$2:$A$15201,'Quoted Spend'!$A3+1,'Raw data'!$M$2:$M$15201,'Quoted Spend'!C$1) -> 381174.85 | D3: =SUMIFS('Raw data'!$AC$2:$AC$15201,'Raw data'!$A$2:$A$15201,'Quoted Spend'!$A3+1,'Raw data'!$M$2:$M$15201,'Quoted Spend'!D$1) -> 375996.88 | E3: =SUMIFS('Raw data'!$AC$2:$AC$15201,'Raw data'!$A$2:$A$15201,'Quoted Spend'!$A3+1,'Raw data'!$M$2:$M$15201,'Quoted Spend'!E$1) -> 345775.29 | F3: =AVERAGE(B3:D3) -> 378544.47
A4: =A3+1 -> 3 | B4: =SUMIFS('Raw data'!$AC$2:$AC$15201,'Raw data'!$A$2:$A$15201,'Quoted Spend'!$A4+1,'Raw data'!$M$2:$M$15201,'Quoted Spend'!B$1) -> 420699.4 | C4: =SUMIFS('Raw data'!$AC$2:$AC$15201,'Raw data'!$A$2:$A$15201,'Quoted Spend'!$A4+1,'Raw data'!$M$2:$M$15201,'Quoted Spend'!C$1) -> 342917.46 | D4: =SUMIFS('Raw data'!$AC$2:$AC$15201,'Raw data'!$A$2:$A$15201,'Quoted Spend'!$A4+1,'Raw data'!$M$2:$M$15201,'Quoted Spend'!D$1) -> 376741.98 | E4: =SUMIFS('Raw data'!$AC$2:$AC$15201,'Raw data'!$A$2:$A$15201,'Quoted Spend'!$A4+1,'Raw data'!$M$2:$M$15201,'Quoted Spend'!E$1) -> 338845.2 | F4: =AVERAGE(B4:D4) -> 380119.61
A5: =A4+1 -> 4 | B5: =SUMIFS('Raw data'!$AC$2:$AC$15201,'Raw data'!$A$2:$A$15201,'Quoted Spend'!$A5+1,'Raw data'!$M$2:$M$15201,'Quoted Spend'!B$1) -> 462543.57 | C5: =SUMIFS('Raw data'!$AC$2:$AC$15201,'Raw data'!$A$2:$A$15201,'Quoted Spend'!$A5+1,'Raw data'!$M$2:$M$15201,'Quoted Spend'!C$1) -> 319768.91 | D5: =SUMIFS('Raw data'!$AC$2:$AC$15201,'Raw data'!$A$2:$A$15201,'Quoted Spend'!$A5+1,'Raw data'!$M$2:$M$15201,'Quoted Spend'!D$1) -> 404123.89 | E5: =SUMIFS('Raw data'!$AC$2:$AC$15201,'Raw data'!$A$2:$A$15201,'Quoted Spend'!$A5+1,'Raw data'!$M$2:$M$15201,'Quoted Spend'!E$1) -> 353887.58 | F5: =AVERAGE(B5:D5) -> 395478.79
A6: =A5+1 -> 5 | B6: =SUMIFS('Raw data'!$AC$2:$AC$15201,'Raw data'!$A$2:$A$15201,'Quoted Spend'!$A6+1,'Raw data'!$M$2:$M$15201,'Quoted Spend'!B$1) -> 408788.44 | C6: =SUMIFS('Raw data'!$AC$2:$AC$15201,'Raw data'!$A$2:$A$15201,'Quoted Spend'!$A6+1,'Raw data'!$M$2:$M$15201,'Quoted Spend'!C$1) -> 361477.52 | D6: =SUMIFS('Raw data'!$AC$2:$AC$15201,'Raw data'!$A$2:$A$15201,'Quoted Spend'!$A6+1,'Raw data'!$M$2:$M$15201,'Quoted Spend'!D$1) -> 310376.54 | E6: =SUMIFS('Raw data'!$AC$2:$AC$15201,'Raw data'!$A$2:$A$15201,'Quoted Spend'!$A6+1,'Raw data'!$M$2:$M$15201,'Quoted Spend'!E$1) -> 360604.06 | F6: =AVERAGE(B6:D6) -> 360214.17
A7: =A6+1 -> 6 | B7: =SUMIFS('Raw data'!$AC$2:$AC$15201,'Raw data'!$A$2:$A$15201,'Quoted Spend'!$A7+1,'Raw data'!$M$2:$M$15201,'Quoted Spend'!B$1) -> 369643.19 | C7: =SUMIFS('Raw data'!$AC$2:$AC$15201,'Raw data'!$A$2:$A$15201,'Quoted Spend'!$A7+1,'Raw data'!$M$2:$M$15201,'Quoted Spend'!C$1) -> 426907.53 | D7: =SUMIFS('Raw data'!$AC$2:$AC$15201,'Raw data'!$A$2:$A$15201,'Quoted Spend'!$A7+1,'Raw data'!$M$2:$M$15201,'Quoted Spend'!D$1) -> 313902.05 | E7: =SUMIFS('Raw data'!$AC$2:$AC$15201,'Raw data'!$A$2:$A$15201,'Quoted Spend'!$A7+1,'Raw data'!$M$2:$M$15201,'Quoted Spend'!E$1) -> 363265.39 | F7: =AVERAGE(B7:D7) -> 370150.92
A8: =A7+1 -> 7 | B8: =SUMIFS('Raw data'!$AC$2:$AC$15201,'Raw data'!$A$2:$A$15201,'Quoted Spend'!$A8+1,'Raw data'!$M$2:$M$15201,'Quoted Spend'!B$1) -> 489790.89 | C8: =SUMIFS('Raw data'!$AC$2:$AC$15201,'Raw data'!$A$2:$A$15201,'Quoted Spend'!$A8+1,'Raw data'!$M$2:$M$15201,'Quoted Spend'!C$1) -> 367971.67 | D8: =SUMIFS('Raw data'!$AC$2:$AC$15201,'Raw data'!$A$2:$A$15201,'Quoted Spend'!$A8+1,'Raw data'!$M$2:$M$15201,'Quoted Spend'!D$1) -> 383515.51 | E8: =SUMIFS('Raw data'!$AC$2:$AC$15201,'Raw data'!$A$2:$A$15201,'Quoted Spend'!$A8+1,'Raw data'!$M$2:$M$15201,'Quoted Spend'!E$1) -> 324602.58 | F8: =AVERAGE(B8:D8) -> 413759.36
A9: =A8+1 -> 8 | B9: =SUMIFS('Raw data'!$AC$2:$AC$15201,'Raw data'!$A$2:$A$15201,'Quoted Spend'!$A9+1,'Raw data'!$M$2:$M$15201,'Quoted Spend'!B$1) -> 366098.27 | C9: =SUMIFS('Raw data'!$AC$2:$AC$15201,'Raw data'!$A$2:$A$15201,'Quoted Spend'!$A9+1,'Raw data'!$M$2:$M$15201,'Quoted Spend'!C$1) -> 384325.77 | D9: =SUMIFS('Raw data'!$AC$2:$AC$15201,'Raw data'!$A$2:$A$15201,'Quoted Spend'!$A9+1,'Raw data'!$M$2:$M$15201,'Quoted Spend'!D$1) -> 377054.38 | E9: =SUMIFS('Raw data'!$AC$2:$AC$15201,'Raw data'!$A$2:$A$15201,'Quoted Spend'!$A9+1,'Raw data'!$M$2:$M$15201,'Quoted Spend'!E$1) -> 351441.23 | F9: =AVERAGE(B9:D9) -> 375826.14
A10: =A9+1 -> 9 | B10: =SUMIFS('Raw data'!$AC$2:$AC$15201,'Raw data'!$A$2:$A$15201,'Quoted Spend'!$A10+1,'Raw data'!$M$2:$M$15201,'Quoted Spend'!B$1) -> 482704.05 | C10: =SUMIFS('Raw data'!$AC$2:$AC$15201,'Raw data'!$A$2:$A$15201,'Quoted Spend'!$A10+1,'Raw data'!$M$2:$M$15201,'Quoted Spend'!C$1) -> 383118.59 | D10: =SUMIFS('Raw data'!$AC$2:$AC$15201,'Raw data'!$A$2:$A$15201,'Quoted Spend'!$A10+1,'Raw data'!$M$2:$M$15201,'Quoted Spend'!D$1) -> 391515.93 | E10: =SUMIFS('Raw data'!$AC$2:$AC$15201,'Raw data'!$A$2:$A$15201,'Quoted Spend'!$A10+1,'Raw data'!$M$2:$M$15201,'Quoted Spend'!E$1) -> 314433.12 | F10: =AVERAGE(B10:D10) -> 419112.86
A11: =A10+1 -> 10 | B11: =SUMIFS('Raw data'!$AC$2:$AC$15201,'Raw data'!$A$2:$A$15201,'Quoted Spend'!$A11+1,'Raw data'!$M$2:$M$15201,'Quoted Spend'!B$1) -> 453402.08 | C11: =SUMIFS('Raw data'!$AC$2:$AC$15201,'Raw data'!$A$2:$A$15201,'Quoted Spend'!$A11+1,'Raw data'!$M$2:$M$15201,'Quoted Spend'!C$1) -> 390724.56 | D11: =SUMIFS('Raw data'!$AC$2:$AC$15201,'Raw data'!$A$2:$A$15201,'Quoted Spend'!$A11+1,'Raw data'!$M$2:$M$15201,'Quoted Spend'!D$1) -> 397939.3 | E11: =SUMIFS('Raw data'!$AC$2:$AC$15201,'Raw data'!$A$2:$A$15201,'Quoted Spend'!$A11+1,'Raw data'!$M$2:$M$15201,'Quoted Spend'!E$1) -> 371001.15 | F11: =AVERAGE(B11:D11) -> 414021.98
A12: =A11+1 -> 11 | B12: =SUMIFS('Raw data'!$AC$2:$AC$15201,'Raw data'!$A$2:$A$15201,'Quoted Spend'!$A12+1,'Raw data'!$M$2:$M$15201,'Quoted Spend'!B$1) -> 420143.84 | C12: =SUMIFS('Raw data'!$AC$2:$AC$15201,'Raw data'!$A$2:$A$15201,'Quoted Spend'!$A12+1,'Raw data'!$M$2:$M$15201,'Quoted Spend'!C$1) -> 315333.23 | D12: =SUMIFS('Raw data'!$AC$2:$AC$15201,'Raw data'!$A$2:$A$15201,'Quoted Spend'!$A12+1,'Raw data'!$M$2:$M$15201,'Quoted Spend'!D$1) -> 374411.49 | E12: =SUMIFS('Raw data'!$AC$2:$AC$15201,'Raw data'!$A$2:$A$15201,'Quoted Spend'!$A12+1,'Raw data'!$M$2:$M$15201,'Quoted Spend'!E$1) -> 388174.24 | F12: =AVERAGE(B12:D12) -> 369962.85
A13: =A12+1 -> 12 | B13: =SUMIFS('Raw data'!$AC$2:$AC$15201,'Raw data'!$A$2:$A$15201,'Quoted Spend'!$A13+1,'Raw data'!$M$2:$M$15201,'Quoted Spend'!B$1) -> 450611.44 | C13: =SUMIFS('Raw data'!$AC$2:$AC$15201,'Raw data'!$A$2:$A$15201,'Quoted Spend'!$A13+1,'Raw data'!$M$2:$M$15201,'Quoted Spend'!C$1) -> 364965.09 | D13: =SUMIFS('Raw data'!$AC$2:$AC$15201,'Raw data'!$A$2:$A$15201,'Quoted Spend'!$A13+1,'Raw data'!$M$2:$M$15201,'Quoted Spend'!D$1) -> 383956.68 | E13: =SUMIFS('Raw data'!$AC$2:$AC$15201,'Raw data'!$A$2:$A$15201,'Quoted Spend'!$A13+1,'Raw data'!$M$2:$M$15201,'Quoted Spend'!E$1) -> 370483.88 | F13: =AVERAGE(B13:D13) -> 399844.4
A14: =A13+1 -> 13 | B14: =SUMIFS('Raw data'!$AC$2:$AC$15201,'Raw data'!$A$2:$A$15201,'Quoted Spend'!$A14+1,'Raw data'!$M$2:$M$15201,'Quoted Spend'!B$1) -> 422688.56 | C14: =SUMIFS('Raw data'!$AC$2:$AC$15201,'Raw data'!$A$2:$A$15201,'Quoted Spend'!$A14+1,'Raw data'!$M$2:$M$15201,'Quoted Spend'!C$1) -> 372789.82 | D14: =SUMIFS('Raw data'!$AC$2:$AC$15201,'Raw data'!$A$2:$A$15201,'Quoted Spend'!$A14+1,'Raw data'!$M$2:$M$15201,'Quoted Spend'!D$1) -> 292012.32 | E14: =SUMIFS('Raw data'!$AC$2:$AC$15201,'Raw data'!$A$2:$A$15201,'Quoted Spend'!$A14+1,'Raw data'!$M$2:$M$15201,'Quoted Spend'!E$1) -> 366519.6 | F14: =AVERAGE(B14:D14) -> 362496.9
... A101: =A100+1 -> 100 | B101: =SUMIFS('Raw data'!$AC$2:$AC$15201,'Raw data'!$A$2:$A$15201,'Quoted Spend'!$A101+1,'Raw data'!$M$2:$M$15201,'Quoted Spend'!B$1) -> 376121.19 | C101: =SUMIFS('Raw data'!$AC$2:$AC$15201,'Raw data'!$A$2:$A$15201,'Quoted Spend'!$A101+1,'Raw data'!$M$2:$M$15201,'Quoted Spend'!C$1) -> 381950.31 | D101: =SUMIFS('Raw data'!$AC$2:$AC$15201,'Raw data'!$A$2:$A$15201,'Quoted Spend'!$A101+1,'Raw data'!$M$2:$M$15201,'Quoted Spend'!D$1) -> 322399.12 | E101: =SUMIFS('Raw data'!$AC$2:$AC$15201,'Raw data'!$A$2:$A$15201,'Quoted Spend'!$A101+1,'Raw data'!$M$2:$M$15201,'Quoted Spend'!E$1) -> 369915.2 | F101: =AVERAGE(B101:D101) -> 360156.87
A102: AVG | B102: =AVERAGE(B2:B101) -> 427411.07 | C102: =AVERAGE(C2:C101) -> 360527.04 | D102: =AVERAGE(D2:D101) -> 362652.3 | E102: =AVERAGE(E2:E101) -> 356339.65 | F102: =AVERAGE(F2:F101) -> 383530.13 | G102: =AVERAGE(B2:D101) -> 383530.13
A103: STDEV | B103: =STDEV(B2:B101) -> 40162.286 | C103: =STDEV(C2:C101) -> 29373.334 | D103: =STDEV(D2:D101) -> 30612.951 | E103: =STDEV(E2:E101) -> 29340.037 | F103: =STDEV(F2:F101) -> 19867.384 | G103: =STDEV(B2:D101) -> 45790.668
