Workbook

Sheet Raw data
A1: Iteration | B1: Project | C1: ECN | D1: ECN release | E1: Part number | F1: Complexity | G1: EAU | H1: Delivery profile | I1: Quotation profile | J1: Price profile | K1: Punctuality profile | L1: Supplier ID | M1: Supplier name | N1: Price | O1: Lead time | P1: RFQ date | Q1: Quotation date | R1: REQ date | S1: PO date | T1: ETA | U1: Delivery date | V1: ISIR documents | W1: ISIR approval | X1: PPAP approval | Y1: Contract date | Z1: Quotation time | AA1: OTD | AB1: Delivery time | AC1: FY Spend | AD1: Awarded | AE1: MCS ready | AF1: Pilot ready | AG1: SOP ready | AH1: Unnamed: 0
A2: 1 | B2: Juneau | C2: ECN0000301 | D2: 45483 | E2: A0A000001 | F2: medium | G2: 224 | H2: regular | I2: low | J2: regular | K2: high | L2: 10000033 | M2: Tuberías ABC, S.A. de C.V. | N2: 3.32 | O2: 30 | P2: 45491 | Q2: 45510 | R2: 45510 | S2: 45516 | T2: 45553 | U2: 45556 | V2: 45556 | W2: 45575 | X2: 45579 | Y2: 45579 | Z2: 19 | AA2: FALSE | AB2: 40 | AC2: 743.68 | AD2: TRUE | AE2: FALSE | AF2: FALSE | AG2: TRUE
A3: 1 | B3: Juneau | C3: ECN0000301 | D3: 45483 | E3: A0D000001 | F3: medium | G3: 224 | H3: regular | I3: low | J3: regular | K3: high | L3: 10000033 | M3: Tuberías ABC, S.A. de C.V. | N3: 82.15 | O3: 30 | P3: 45491 | Q3: 45510 | R3: 45510 | S3: 45516 | T3: 45553 | U3: 45556 | V3: 45556 | W3: 45575 | X3: 45579 | Y3: 45579 | Z3: 19 | AA3: FALSE | AB3: 40 | AC3: 18401.6 | AD3: TRUE | AE3: FALSE | AF3: FALSE | AG3: TRUE
A4: 1 | B4: Juneau | C4: ECN0000302 | D4: 45490 | E4: A0A000002 | F4: medium | G4: 23 | H4: low | I4: low | J4: low | K4: high | L4: 10000082 | M4: Tuberías Súper, S.A.P.I. | N4: 31.19 | P4: 45493 | Q4: 45500 | R4: 45514 | S4: 45519 | T4: 45539 | U4: 45538 | V4: 45538 | W4: 45559 | X4: 45559 | Y4: 45562 | Z4: 7.2 | AA4: TRUE | AB4: 19 | AC4: 717.37 | AD4: TRUE | AE4: FALSE | AF4: FALSE | AG4: TRUE
A5: 1 | B5: Juneau | C5: ECN0000302 | D5: 45490 | E5: A0A000003 | F5: low | G5: 23 | H5: low | I5: low | J5: low | K5: high | L5: 10000082 | M5: Tuberías Súper, S.A.P.I. | N5: 28.34 | P5: 45493 | Q5: 45500 | R5: 45514 | S5: 45519 | T5: 45539 | U5: 45538 | V5: 45538 | W5: 45559 | X5: 45559 | Y5: 45562 | Z5: 7.2 | AA5: TRUE | AB5: 19 | AC5: 651.82 | AD5: TRUE | AE5: FALSE | AF5: FALSE | AG5: TRUE
A6: 1 | B6: Juneau | C6: ECN0000302 | D6: 45490 | E6: A0A000004 | F6: low | G6: 23 | H6: low | I6: low | J6: low | K6: high | L6: 10000082 | M6: Tuberías Súper, S.A.P.I. | N6: 14.28 | P6: 45493 | Q6: 45500 | R6: 45514 | S6: 45519 | T6: 45539 | U6: 45538 | V6: 45538 | W6: 45559 | X6: 45559 | Y6: 45562 | Z6: 7.2 | AA6: TRUE | AB6: 19 | AC6: 328.44 | AD6: TRUE | AE6: FALSE | AF6: FALSE | AG6: TRUE
A7: 1 | B7: Juneau | C7: ECN0000302 | D7: 45490 | E7: A0A000005 | F7: low | G7: 23 | H7: low | I7: low | J7: low | K7: high | L7: 10000082 | M7: Tuberías Súper, S.A.P.I. | N7: 19.56 | P7: 45493 | Q7: 45500 | R7: 45514 | S7: 45519 | T7: 45539 | U7: 45538 | V7: 45538 | W7: 45559 | X7: 45559 | Y7: 45562 | Z7: 7.2 | AA7: TRUE | AB7: 19 | AC7: 449.88 | AD7: TRUE | AE7: FALSE | AF7: FALSE | AG7: TRUE
A8: 1 | B8: Juneau | C8: ECN0000303 | D8: 45493 | E8: A0A000006 | F8: medium | G8: 295 | H8: regular | I8: low | J8: regular | K8: high | L8: 10000033 | M8: Tuberías ABC, S.A. de C.V. | N8: 12.25 | O8: 30 | P8: 45496 | Q8: 45520 | R8: 45533 | S8: 45533 | T8: 45573 | U8: 45573 | V8: 45573 | W8: 45596 | X8: 45596 | Y8: 45604 | Z8: 24 | AA8: TRUE | AB8: 40 | AC8: 3613.75 | AD8: TRUE | AE8: FALSE | AF8: FALSE | AG8: FALSE
A9: 1 | B9: Juneau | C9: ECN0000303 | D9: 45493 | E9: A0A000007 | F9: low | G9: 295 | H9: regular | I9: low | J9: regular | K9: high | L9: 10000033 | M9: Tuberías ABC, S.A. de C.V. | N9: 24.73 | O9: 30 | P9: 45496 | Q9: 45520 | R9: 45533 | S9: 45533 | T9: 45573 | U9: 45573 | V9: 45573 | W9: 45596 | X9: 45596 | Y9: 45604 | Z9: 24 | AA9: TRUE | AB9: 40 | AC9: 7295.35 | AD9: TRUE | AE9: FALSE | AF9: FALSE | AG9: FALSE
A10: 1 | B10: Juneau | C10: ECN0000303 | D10: 45493 | E10: A0G000334 | F10: high | G10: 295 | H10: regular | I10: low | J10: regular | K10: high | L10: 10000033 | M10: Tuberías ABC, S.A. de C.V. | N10: 113.3 | O10: 30 | P10: 45496 | Q10: 45520 | R10: 45533 | S10: 45533 | T10: 45573 | U10: 45573 | V10: 45573 | W10: 45596 | X10: 45596 | Y10: 45604 | Z10: 24 | AA10: TRUE | AB10: 40 | AC10: 33423.5 | AD10: TRUE | AE10: FALSE | AF10: FALSE | AG10: FALSE
A11: 1 | B11: Juneau | C11: ECN0000304 | D11: 45329 | E11: A0E000001 | F11: high | G11: 256 | H11: regular | I11: high | J11: low | K11: regular | L11: 10000047 | M11: Tuberías DEF, S. de R.L. | N11: 119.61 | O11: 14 | P11: 45339 | Q11: 45403 | R11: 45418 | S11: 45426 | T11: 45451 | U11: 45450 | V11: 45450 | W11: 45492 | X11: 45497 | Y11: 45506 | Z11: 64 | AA11: TRUE | AB11: 24 | AC11: 30620.16 | AD11: TRUE | AE11: TRUE | AF11: TRUE | AG11: TRUE
A12: 1 | B12: Juneau | C12: ECN0000304 | D12: 45329 | E12: A0E000002 | F12: high | G12: 256 | H12: regular | I12: high | J12: low | K12: regular | L12: 10000047 | M12: Tuberías DEF, S. de R.L. | N12: 73.55 | O12: 14 | P12: 45339 | Q12: 45403 | R12: 45418 | S12: 45426 | T12: 45451 | U12: 45450 | V12: 45450 | W12: 45492 | X12: 45497 | Y12: 45506 | Z12: 64 | AA12: TRUE | AB12: 24 | AC12: 18828.8 | AD12: TRUE | AE12: TRUE | AF12: TRUE | AG12: TRUE
A13: 1 | B13: Juneau | C13: ECN0000304 | D13: 45329 | E13: A0E000003 | F13: high | G13: 256 | H13: regular | I13: high | J13: low | K13: regular | L13: 10000047 | M13: Tuberías DEF, S. de R.L. | N13: 75.71 | O13: 14 | P13: 45339 | Q13: 45403 | R13: 45418 | S13: 45426 | T13: 45451 | U13: 45450 | V13: 45450 | W13: 45492 | X13: 45497 | Y13: 45506 | Z13: 64 | AA13: TRUE | AB13: 24 | AC13: 19381.76 | AD13: TRUE | AE13: TRUE | AF13: TRUE | AG13: TRUE
A14: 1 | B14: Juneau | C14: ECN0000305 | D14: 45356 | E14: A0A000008 | F14: low | G14: 23 | H14: high | I14: high | J14: low | K14: low | L14: 10000073 | M14: Tuberías GHI, S.A.S. | N14: 2.77 | O14: 28 | P14: 45361 | Q14: 45434 | R14: 45437 | S14: 45446 | T14: 45479 | U14: 45480 | V14: 45480 | W14: 45480 | X14: 45488 | Y14: 45488 | Z14: 73 | AA14: FALSE | AB14: 34 | AC14: 63.71 | AD14: TRUE | AE14: FALSE | AF14: TRUE | AG14: TRUE
A15: 1 | B15: Juneau | C15: ECN0000305 | D15: 45356 | E15: A0A000009 | F15: low | G15: 23 | H15: high | I15: high | J15: low | K15: low | L15: 10000073 | M15: Tuberías GHI, S.A.S. | N15: 7.73 | O15: 28 | P15: 45361 | Q15: 45434 | R15: 45437 | S15: 45446 | T15: 45479 | U15: 45480 | V15: 45480 | W15: 45480 | X15: 45488 | Y15: 45488 | Z15: 73 | AA15: FALSE | AB15: 34 | AC15: 177.79 | AD15: TRUE | AE15: FALSE | AF15: TRUE | AG15: TRUE
A16: 1 | B16: Juneau | C16: ECN0000305 | D16: 45356 | E16: A0A000010 | F16: medium | G16: 23 | H16: high | I16: high | J16: low | K16: low | L16: 10000073 | M16: Tuberías GHI, S.A.S. | N16: 52.64 | O16: 28 | P16: 45361 | Q16: 45434 | R16: 45437 | S16: 45446 | T16: 45479 | U16: 45480 | V16: 45480 | W16: 45480 | X16: 45488 | Y16: 45488 | Z16: 73 | AA16: FALSE | AB16: 34 | AC16: 1210.72 | AD16: TRUE | AE16: FALSE | AF16: TRUE | AG16: TRUE
A17: 1 | B17: Juneau | C17: ECN0000305 | D17: 45356 | E17: A0D000002 | F17: medium | G17: 23 | H17: high | I17: high | J17: low | K17: low | L17: 10000073 | M17: Tuberías GHI, S.A.S. | N17: 34.22 | O17: 28 | P17: 45361 | Q17: 45434 | R17: 45437 | S17: 45446 | T17: 45479 | U17: 45480 | V17: 45480 | W17: 45480 | X17: 45488 | Y17: 45488 | Z17: 73 | AA17: FALSE | AB17: 34 | AC17: 787.06 | AD17: TRUE | AE17: FALSE | AF17: TRUE | AG17: TRUE
A18: 1 | B18: Juneau | C18: ECN0000306 | D18: 45546 | E18: A0A000011 | F18: medium | G18: 23 | H18: regular | I18: low | J18: regular | K18: high | L18: 10000033 | M18: Tuberías ABC, S.A. de C.V. | N18: 1.93 | O18: 30 | P18: 45546 | Q18: 45553 | R18: 45574 | S18: 45581 | T18: 45632 | U18: 45631 | V18: 45633 | W18: 45658 | X18: 45658 | Y18: 45659 | Z18: 7.2 | AA18: TRUE | AB18: 50 | AC18: 44.39 | AD18: TRUE | AE18: FALSE | AF18: FALSE | AG18: FALSE
A19: 1 | B19: Juneau | C19: ECN0000306 | D19: 45546 | E19: A0A000012 | F19: low | G19: 23 | H19: regular | I19: low | J19: regular | K19: high | L19: 10000033 | M19: Tuberías ABC, S.A. de C.V. | N19: 9.41 | O19: 30 | P19: 45546 | Q19: 45553 | R19: 45574 | S19: 45581 | T19: 45632 | U19: 45631 | V19: 45633 | W19: 45658 | X19: 45658 | Y19: 45659 | Z19: 7.2 | AA19: TRUE | AB19: 50 | AC19: 216.43 | AD19: TRUE | AE19: FALSE | AF19: FALSE | AG19: FALSE
A20: 1 | B20: Juneau | C20: ECN0000306 | D20: 45546 | E20: A0D000003 | F20: medium | G20: 23 | H20: regular | I20: low | J20: regular | K20: high | L20: 10000033 | M20: Tuberías ABC, S.A. de C.V. | N20: 50.51 | O20: 30 | P20: 45546 | Q20: 45553 | R20: 45574 | S20: 45581 | T20: 45632 | U20: 45631 | V20: 45633 | W20: 45658 | X20: 45658 | Y20: 45659 | Z20: 7.2 | AA20: TRUE | AB20: 50 | AC20: 1161.73 | AD20: TRUE | AE20: FALSE | AF20: FALSE | AG20: FALSE
A21: 1 | B21: Juneau | C21: ECN0000307 | D21: 45400 | E21: A0A000013 | F21: low | G21: 242 | H21: low | I21: low | J21: low | K21: high | L21: 10000082 | M21: Tuberías Súper, S.A.P.I. | N21: 9.88 | P21: 45410 | Q21: 45426 | R21: 45440 | S21: 45446 | T21: 45489 | U21: 45495 | V21: 45497 | W21: 45546 | X21: 45546 | Y21: 45546 | Z21: 16 | AA21: FALSE | AB21: 49 | AC21: 2390.96 | AD21: TRUE | AE21: FALSE | AF21: FALSE | AG21: TRUE
A22: 1 | B22: Juneau | C22: ECN0000307 | D22: 45400 | E22: A0C000001 | F22: low | G22: 242 | H22: low | I22: low | J22: low | K22: high | L22: 10000082 | M22: Tuberías Súper, S.A.P.I. | N22: 19.9 | P22: 45410 | Q22: 45426 | R22: 45440 | S22: 45446 | T22: 45489 | U22: 45495 | V22: 45497 | W22: 45546 | X22: 45546 | Y22: 45546 | Z22: 16 | AA22: FALSE | AB22: 49 | AC22: 4815.8 | AD22: TRUE | AE22: FALSE | AF22: FALSE | AG22: TRUE
A23: 1 | B23: Juneau | C23: ECN0000307 | D23: 45400 | E23: A0D000004 | F23: medium | G23: 242 | H23: low | I23: low | J23: low | K23: high | L23: 10000082 | M23: Tuberías Súper, S.A.P.I. | N23: 54.79 | P23: 45410 | Q23: 45426 | R23: 45440 | S23: 45446 | T23: 45489 | U23: 45495 | V23: 45497 | W23: 45546 | X23: 45546 | Y23: 45546 | Z23: 16 | AA23: FALSE | AB23: 49 | AC23: 13259.18 | AD23: TRUE | AE23: FALSE | AF23: FALSE | AG23: TRUE
A24: 1 | B24: Juneau | C24: ECN0000307 | D24: 45400 | E24: A0E000004 | F24: high | G24: 242 | H24: low | I24: low | J24: low | K24: high | L24: 10000082 | M24: Tuberías Súper, S.A.P.I. | N24: 140.61 | P24: 45410 | Q24: 45426 | R24: 45440 | S24: 45446 | T24: 45489 | U24: 45495 | V24: 45497 | W24: 45546 | X24: 45546 | Y24: 45546 | Z24: 16 | AA24: FALSE | AB24: 49 | AC24: 34027.62 | AD24: TRUE | AE24: FALSE | AF24: FALSE | AG24: TRUE
A25: 1 | B25: Juneau | C25: ECN0000307 | D25: 45400 | E25: A0E000005 | F25: high | G25: 242 | H25: low | I25: low | J25: low | K25: high | L25: 10000082 | M25: Tuberías Súper, S.A.P.I. | N25: 52.36 | P25: 45410 | Q25: 45426 | R25: 45440 | S25: 45446 | T25: 45489 | U25: 45495 | V25: 45497 | W25: 45546 | X25: 45546 | Y25: 45546 | Z25: 16 | AA25: FALSE | AB25: 49 | AC25: 12671.12 | AD25: TRUE | AE25: FALSE | AF25: FALSE | AG25: TRUE
A26: 1 | B26: Juneau | C26: ECN0000307 | D26: 45400 | E26: A0G000335 | F26: high | G26: 242 | H26: low | I26: low | J26: low | K26: high | L26: 10000082 | M26: Tuberías Súper, S.A.P.I. | N26: 118.13 | P26: 45410 | Q26: 45426 | R26: 45440 | S26: 45446 | T26: 45489 | U26: 45495 | V26: 45497 | W26: 45546 | X26: 45546 | Y26: 45546 | Z26: 16 | AA26: FALSE | AB26: 49 | AC26: 28587.46 | AD26: TRUE | AE26: FALSE | AF26: FALSE | AG26: TRUE
A27: 1 | B27: Juneau | C27: ECN0000307 | D27: 45400 | E27: A0G000336 | F27: high | G27: 242 | H27: low | I27: low | J27: low | K27: high | L27: 10000082 | M27: Tuberías Súper, S.A.P.I. | N27: 64.73 | P27: 45410 | Q27: 45426 | R27: 45440 | S27: 45446 | T27: 45489 | U27: 45495 | V27: 45497 | W27: 45546 | X27: 45546 | Y27: 45546 | Z27: 16 | AA27: FALSE | AB27: 49 | AC27: 15664.66 | AD27: TRUE | AE27: FALSE | AF27: FALSE | AG27: TRUE
A28: 1 | B28: Juneau | C28: ECN0000308 | D28: 45422 | E28: A0A000014 | F28: low | G28: 156 | H28: regular | I28: high | J28: low | K28: regular | L28: 10000047 | M28: Tuberías DEF, S. de R.L. | N28: 8.33 | O28: 14 | P28: 45425 | Q28: 45473 | R28: 45481 | S28: 45488 | T28: 45500 | U28: 45499 | V28: 45499 | W28: 45564 | X28: 45564 | Y28: 45564 | Z28: 48 | AA28: TRUE | AB28: 11 | AC28: 1299.48 | AD28: TRUE | AE28: FALSE | AF28: FALSE | AG28: TRUE
A29: 1 | B29: Juneau | C29: ECN0000308 | D29: 45422 | E29: A0A000015 | F29: medium | G29: 156 | H29: regular | I29: high | J29: low | K29: regular | L29: 10000047 | M29: Tuberías DEF, S. de R.L. | N29: 70.58 | O29: 14 | P29: 45425 | Q29: 45473 | R29: 45481 | S29: 45488 | T29: 45500 | U29: 45499 | V29: 45499 | W29: 45564 | X29: 45564 | Y29: 45564 | Z29: 48 | AA29: TRUE | AB29: 11 | AC29: 11010.48 | AD29: TRUE | AE29: FALSE | AF29: FALSE | AG29: TRUE
A30: 1 | B30: Juneau | C30: ECN0000308 | D30: 45422 | E30: A0C000002 | F30: low | G30: 156 | H30: regular | I30: high | J30: low | K30: regular | L30: 10000047 | M30: Tuberías DEF, S. de R.L. | N30: 12.53 | O30: 14 | P30: 45425 | Q30: 45473 | R30: 45481 | S30: 45488 | T30: 45500 | U30: 45499 | V30: 45499 | W30: 45564 | X30: 45564 | Y30: 45564 | Z30: 48 | AA30: TRUE | AB30: 11 | AC30: 1954.68 | AD30: TRUE | AE30: FALSE | AF30: FALSE | AG30: TRUE
A31: 1 | B31: Juneau | C31: ECN0000308 | D31: 45422 | E31: A0C000003 | F31: low | G31: 156 | H31: regular | I31: high | J31: low | K31: regular | L31: 10000047 | M31: Tuberías DEF, S. de R.L. | N31: 18.14 | O31: 14 | P31: 45425 | Q31: 45473 | R31: 45481 | S31: 45488 | T31: 45500 | U31: 45499 | V31: 45499 | W31: 45564 | X31: 45564 | Y31: 45564 | Z31: 48 | AA31: TRUE | AB31: 11 | AC31: 2829.84 | AD31: TRUE | AE31: FALSE | AF31: FALSE | AG31: TRUE
A32: 1 | B32: Juneau | C32: ECN0000308 | D32: 45422 | E32: A0G000337 | F32: high | G32: 156 | H32: regular | I32: high | J32: low | K32: regular | L32: 10000047 | M32: Tuberías DEF, S. de R.L. | N32: 97.44 | O32: 14 | P32: 45425 | Q32: 45473 | R32: 45481 | S32: 45488 | T32: 45500 | U32: 45499 | V32: 45499 | W32: 45564 | X32: 45564 | Y32: 45564 | Z32: 48 | AA32: TRUE | AB32: 11 | AC32: 15200.64 | AD32: TRUE | AE32: FALSE | AF32: FALSE | AG32: TRUE
A33: 1 | B33: Juneau | C33: ECN0000309 | D33: 45386 | E33: A0A000016 | F33: low | G33: 554 | H33: high | I33: high | J33: low | K33: low | L33: 10000073 | M33: Tuberías GHI, S.A.S. | N33: 10.18 | O33: 28 | P33: 45392 | Q33: 45432 | R33: 45436 | S33: 45441 | T33: 45466 | U33: 45471 | V33: 45472 | W33: 45472 | X33: 45481 | Y33: 45482 | Z33: 40 | AA33: FALSE | AB33: 30 | AC33: 5639.72 | AD33: TRUE | AE33: FALSE | AF33: TRUE | AG33: TRUE
A34: 1 | B34: Juneau | C34: ECN0000309 | D34: 45386 | E34: A0B000001 | F34: medium | G34: 554 | H34: high | I34: high | J34: low | K34: low | L34: 10000073 | M34: Tuberías GHI, S.A.S. | N34: 12.67 | O34: 28 | P34: 45392 | Q34: 45432 | R34: 45436 | S34: 45441 | T34: 45466 | U34: 45471 | V34: 45472 | W34: 45472 | X34: 45481 | Y34: 45482 | Z34: 40 | AA34: FALSE | AB34: 30 | AC34: 7019.18 | AD34: TRUE | AE34: FALSE | AF34: TRUE | AG34: TRUE
A35: 1 | B35: Juneau | C35: ECN0000309 | D35: 45386 | E35: A0B000002 | F35: medium | G35: 554 | H35: high | I35: high | J35: low | K35: low | L35: 10000073 | M35: Tuberías GHI, S.A.S. | N35: 8.06 | O35: 28 | P35: 45392 | Q35: 45432 | R35: 45436 | S35: 45441 | T35: 45466 | U35: 45471 | V35: 45472 | W35: 45472 | X35: 45481 | Y35: 45482 | Z35: 40 | AA35: FALSE | AB35: 30 | AC35: 4465.24 | AD35: TRUE | AE35: FALSE | AF35: TRUE | AG35: TRUE
A36: 1 | B36: Juneau | C36: ECN0000309 | D36: 45386 | E36: A0G000338 | F36: high | G36: 554 | H36: high | I36: high | J36: low | K36: low | L36: 10000073 | M36: Tuberías GHI, S.A.S. | N36: 96.88 | O36: 28 | P36: 45392 | Q36: 45432 | R36: 45436 | S36: 45441 | T36: 45466 | U36: 45471 | V36: 45472 | W36: 45472 | X36: 45481 | Y36: 45482 | Z36: 40 | AA36: FALSE | AB36: 30 | AC36: 53671.52 | AD36: TRUE | AE36: FALSE | AF36: TRUE | AG36: TRUE
A37: 1 | B37: Juneau | C37: ECN0000310 | D37: 45525 | E37: A0A000017 | F37: low | G37: 23 | H37: high | I37: high | J37: low | K37: low | L37: 10000073 | M37: Tuberías GHI, S.A.S. | N37: 13.33 | O37: 28 | P37: 45525 | Q37: 45541 | R37: 45551 | S37: 45562 | T37: 45596 | U37: 45595 | V37: 45596 | W37: 45636 | X37: 45638 | Y37: 45641 | Z37: 16 | AA37: TRUE | AB37: 33 | AC37: 306.59 | AD37: TRUE | AE37: FALSE | AF37: FALSE | AG37: FALSE
A38: 1 | B38: Juneau | C38: ECN0000310 | D38: 45525 | E38: A0A000018 | F38: low | G38: 23 | H38: high | I38: high | J38: low | K38: low | L38: 10000073 | M38: Tuberías GHI, S.A.S. | N38: 14.62 | O38: 28 | P38: 45525 | Q38: 45541 | R38: 45551 | S38: 45562 | T38: 45596 | U38: 45595 | V38: 45596 | W38: 45636 | X38: 45638 | Y38: 45641 | Z38: 16 | AA38: TRUE | AB38: 33 | AC38: 336.26 | AD38: TRUE | AE38: FALSE | AF38: FALSE | AG38: FALSE
A39: 1 | B39: Juneau | C39: ECN0000310 | D39: 45525 | E39: A0D000005 | F39: medium | G39: 23 | H39: high | I39: high | J39: low | K39: low | L39: 10000073 | M39: Tuberías GHI, S.A.S. | N39: 61.25 | O39: 28 | P39: 45525 | Q39: 45541 | R39: 45551 | S39: 45562 | T39: 45596 | U39: 45595 | V39: 45596 | W39: 45636 | X39: 45638 | Y39: 45641 | Z39: 16 | AA39: TRUE | AB39: 33 | AC39: 1408.75 | AD39: TRUE | AE39: FALSE | AF39: FALSE | AG39: FALSE
... A41: 2 | B41: Juneau | C41: ECN0000301 | D41: 45483 | E41: A0D000001 | F41: medium | G41: 224 | H41: regular | I41: high | J41: low | K41: regular | L41: 10000047 | M41: Tuberías DEF, S. de R.L. | N41: 47.83 | O41: 14 | P41: 45485 | Q41: 45496 | R41: 45496 | S41: 45504 | T41: 45564 | U41: 45564 | V41: 45564 | W41: 45564 | X41: 45564 | Y41: 45564 | Z41: 11.7 | AA41: TRUE | AB41: 60 | AC41: 10713.92 | AD41: TRUE | AE41: FALSE | AF41: FALSE | AG41: TRUE
...

Sheet PN
A1: Iteration | B1: Tuberías ABC, S.A. de C.V. | C1: Tuberías DEF, S. de R.L. | D1: Tuberías GHI, S.A.S. | E1: Tuberías Súper, S.A.P.I. | F1: Total
A2: 1 | B2: =COUNTIFS('Raw data'!$A:$A,PN!$A2,'Raw data'!$M:$M,PN!B$1,'Raw data'!$AD:$AD,TRUE) -> 8 | C2: =COUNTIFS('Raw data'!$A:$A,PN!$A2,'Raw data'!$M:$M,PN!C$1,'Raw data'!$AD:$AD,TRUE) -> 8 | D2: =COUNTIFS('Raw data'!$A:$A,PN!$A2,'Raw data'!$M:$M,PN!D$1,'Raw data'!$AD:$AD,TRUE) -> 11 | E2: =COUNTIFS('Raw data'!$A:$A,PN!$A2,'Raw data'!$M:$M,PN!E$1,'Raw data'!$AD:$AD,TRUE) -> 11 | F2: =SUM(B2:E2) -> 38
A3: =A2+1 -> 2 | B3: =COUNTIFS('Raw data'!$A:$A,PN!$A3,'Raw data'!$M:$M,PN!B$1,'Raw data'!$AD:$AD,TRUE) -> 7 | C3: =COUNTIFS('Raw data'!$A:$A,PN!$A3,'Raw data'!$M:$M,PN!C$1,'Raw data'!$AD:$AD,TRUE) -> 9 | D3: =COUNTIFS('Raw data'!$A:$A,PN!$A3,'Raw data'!$M:$M,PN!D$1,'Raw data'!$AD:$AD,TRUE) -> 8 | E3: =COUNTIFS('Raw data'!$A:$A,PN!$A3,'Raw data'!$M:$M,PN!E$1,'Raw data'!$AD:$AD,TRUE) -> 14 | F3: =SUM(B3:E3) -> 38
A4: =A3+1 -> 3 | B4: =COUNTIFS('Raw data'!$A:$A,PN!$A4,'Raw data'!$M:$M,PN!B$1,'Raw data'!$AD:$AD,TRUE) -> 9 | C4: =COUNTIFS('Raw data'!$A:$A,PN!$A4,'Raw data'!$M:$M,PN!C$1,'Raw data'!$AD:$AD,TRUE) -> 3 | D4: =COUNTIFS('Raw data'!$A:$A,PN!$A4,'Raw data'!$M:$M,PN!D$1,'Raw data'!$AD:$AD,TRUE) -> 9 | E4: =COUNTIFS('Raw data'!$A:$A,PN!$A4,'Raw data'!$M:$M,PN!E$1,'Raw data'!$AD:$AD,TRUE) -> 17 | F4: =SUM(B4:E4) -> 38
A5: =A4+1 -> 4 | B5: =COUNTIFS('Raw data'!$A:$A,PN!$A5,'Raw data'!$M:$M,PN!B$1,'Raw data'!$AD:$AD,TRUE) -> 9 | C5: =COUNTIFS('Raw data'!$A:$A,PN!$A5,'Raw data'!$M:$M,PN!C$1,'Raw data'!$AD:$AD,TRUE) -> 4 | D5: =COUNTIFS('Raw data'!$A:$A,PN!$A5,'Raw data'!$M:$M,PN!D$1,'Raw data'!$AD:$AD,TRUE) -> 10 | E5: =COUNTIFS('Raw data'!$A:$A,PN!$A5,'Raw data'!$M:$M,PN!E$1,'Raw data'!$AD:$AD,TRUE) -> 15 | F5: =SUM(B5:E5) -> 38
A6: =A5+1 -> 5 | B6: =COUNTIFS('Raw data'!$A:$A,PN!$A6,'Raw data'!$M:$M,PN!B$1,'Raw data'!$AD:$AD,TRUE) -> 6 | C6: =COUNTIFS('Raw data'!$A:$A,PN!$A6,'Raw data'!$M:$M,PN!C$1,'Raw data'!$AD:$AD,TRUE) -> 20 | D6: =COUNTIFS('Raw data'!$A:$A,PN!$A6,'Raw data'!$M:$M,PN!D$1,'Raw data'!$AD:$AD,TRUE) -> 7 | E6: =COUNTIFS('Raw data'!$A:$A,PN!$A6,'Raw data'!$M:$M,PN!E$1,'Raw data'!$AD:$AD,TRUE) -> 5 | F6: =SUM(B6:E6) -> 38
A7: =A6+1 -> 6 | B7: =COUNTIFS('Raw data'!$A:$A,PN!$A7,'Raw data'!$M:$M,PN!B$1,'Raw data'!$AD:$AD,TRUE) -> 7 | C7: =COUNTIFS('Raw data'!$A:$A,PN!$A7,'Raw data'!$M:$M,PN!C$1,'Raw data'!$AD:$AD,TRUE) -> 18 | D7: =COUNTIFS('Raw data'!$A:$A,PN!$A7,'Raw data'!$M:$M,PN!D$1,'Raw data'!$AD:$AD,TRUE) -> 0 | E7: =COUNTIFS('Raw data'!$A:$A,PN!$A7,'Raw data'!$M:$M,PN!E$1,'Raw data'!$AD:$AD,TRUE) -> 13 | F7: =SUM(B7:E7) -> 38
A8: =A7+1 -> 7 | B8: =COUNTIFS('Raw data'!$A:$A,PN!$A8,'Raw data'!$M:$M,PN!B$1,'Raw data'!$AD:$AD,TRUE) -> 3 | C8: =COUNTIFS('Raw data'!$A:$A,PN!$A8,'Raw data'!$M:$M,PN!C$1,'Raw data'!$AD:$AD,TRUE) -> 12 | D8: =COUNTIFS('Raw data'!$A:$A,PN!$A8,'Raw data'!$M:$M,PN!D$1,'Raw data'!$AD:$AD,TRUE) -> 10 | E8: =COUNTIFS('Raw data'!$A:$A,PN!$A8,'Raw data'!$M:$M,PN!E$1,'Raw data'!$AD:$AD,TRUE) -> 13 | F8: =SUM(B8:E8) -> 38
A9: =A8+1 -> 8 | B9: =COUNTIFS('Raw data'!$A:$A,PN!$A9,'Raw data'!$M:$M,PN!B$1,'Raw data'!$AD:$AD,TRUE) -> 4 | C9: =COUNTIFS('Raw data'!$A:$A,PN!$A9,'Raw data'!$M:$M,PN!C$1,'Raw data'!$AD:$AD,TRUE) -> 17 | D9: =COUNTIFS('Raw data'!$A:$A,PN!$A9,'Raw data'!$M:$M,PN!D$1,'Raw data'!$AD:$AD,TRUE) -> 3 | E9: =COUNTIFS('Raw data'!$A:$A,PN!$A9,'Raw data'!$M:$M,PN!E$1,'Raw data'!$AD:$AD,TRUE) -> 14 | F9: =SUM(B9:E9) -> 38
A10: =A9+1 -> 9 | B10: =COUNTIFS('Raw data'!$A:$A,PN!$A10,'Raw data'!$M:$M,PN!B$1,'Raw data'!$AD:$AD,TRUE) -> 3 | C10: =COUNTIFS('Raw data'!$A:$A,PN!$A10,'Raw data'!$M:$M,PN!C$1,'Raw data'!$AD:$AD,TRUE) -> 23 | D10: =COUNTIFS('Raw data'!$A:$A,PN!$A10,'Raw data'!$M:$M,PN!D$1,'Raw data'!$AD:$AD,TRUE) -> 8 | E10: =COUNTIFS('Raw data'!$A:$A,PN!$A10,'Raw data'!$M:$M,PN!E$1,'Raw data'!$AD:$AD,TRUE) -> 4 | F10: =SUM(B10:E10) -> 38
A11: =A10+1 -> 10 | B11: =COUNTIFS('Raw data'!$A:$A,PN!$A11,'Raw data'!$M:$M,PN!B$1,'Raw data'!$AD:$AD,TRUE) -> 8 | C11: =COUNTIFS('Raw data'!$A:$A,PN!$A11,'Raw data'!$M:$M,PN!C$1,'Raw data'!$AD:$AD,TRUE) -> 11 | D11: =COUNTIFS('Raw data'!$A:$A,PN!$A11,'Raw data'!$M:$M,PN!D$1,'Raw data'!$AD:$AD,TRUE) -> 13 | E11: =COUNTIFS('Raw data'!$A:$A,PN!$A11,'Raw data'!$M:$M,PN!E$1,'Raw data'!$AD:$AD,TRUE) -> 6 | F11: =SUM(B11:E11) -> 38
A12: =A11+1 -> 11 | B12: =COUNTIFS('Raw data'!$A:$A,PN!$A12,'Raw data'!$M:$M,PN!B$1,'Raw data'!$AD:$AD,TRUE) -> 18 | C12: =COUNTIFS('Raw data'!$A:$A,PN!$A12,'Raw data'!$M:$M,PN!C$1,'Raw data'!$AD:$AD,TRUE) -> 3 | D12: =COUNTIFS('Raw data'!$A:$A,PN!$A12,'Raw data'!$M:$M,PN!D$1,'Raw data'!$AD:$AD,TRUE) -> 13 | E12: =COUNTIFS('Raw data'!$A:$A,PN!$A12,'Raw data'!$M:$M,PN!E$1,'Raw data'!$AD:$AD,TRUE) -> 4 | F12: =SUM(B12:E12) -> 38
A13: =A12+1 -> 12 | B13: =COUNTIFS('Raw data'!$A:$A,PN!$A13,'Raw data'!$M:$M,PN!B$1,'Raw data'!$AD:$AD,TRUE) -> 6 | C13: =COUNTIFS('Raw data'!$A:$A,PN!$A13,'Raw data'!$M:$M,PN!C$1,'Raw data'!$AD:$AD,TRUE) -> 18 | D13: =COUNTIFS('Raw data'!$A:$A,PN!$A13,'Raw data'!$M:$M,PN!D$1,'Raw data'!$AD:$AD,TRUE) -> 4 | E13: =COUNTIFS('Raw data'!$A:$A,PN!$A13,'Raw data'!$M:$M,PN!E$1,'Raw data'!$AD:$AD,TRUE) -> 10 | F13: =SUM(B13:E13) -> 38
A14: =A13+1 -> 13 | B14: =COUNTIFS('Raw data'!$A:$A,PN!$A14,'Raw data'!$M:$M,PN!B$1,'Raw data'!$AD:$AD,TRUE) -> 13 | C14: =COUNTIFS('Raw data'!$A:$A,PN!$A14,'Raw data'!$M:$M,PN!C$1,'Raw data'!$AD:$AD,TRUE) -> 18 | D14: =COUNTIFS('Raw data'!$A:$A,PN!$A14,'Raw data'!$M:$M,PN!D$1,'Raw data'!$AD:$AD,TRUE) -> 7 | E14: =COUNTIFS('Raw data'!$A:$A,PN!$A14,'Raw data'!$M:$M,PN!E$1,'Raw data'!$AD:$AD,TRUE) -> 0 | F14: =SUM(B14:E14) -> 38
... A101: =A100+1 -> 100 | B101: =COUNTIFS('Raw data'!$A:$A,PN!$A101,'Raw data'!$M:$M,PN!B$1,'Raw data'!$AD:$AD,TRUE) -> 9 | C101: =COUNTIFS('Raw data'!$A:$A,PN!$A101,'Raw data'!$M:$M,PN!C$1,'Raw data'!$AD:$AD,TRUE) -> 4 | D101: =COUNTIFS('Raw data'!$A:$A,PN!$A101,'Raw data'!$M:$M,PN!D$1,'Raw data'!$AD:$AD,TRUE) -> 15 | E101: =COUNTIFS('Raw data'!$A:$A,PN!$A101,'Raw data'!$M:$M,PN!E$1,'Raw data'!$AD:$AD,TRUE) -> 10 | F101: =SUM(B101:E101) -> 38
A102: AVG | B102: =AVERAGE(B2:B101) -> 8.61 | C102: =AVERAGE(C2:C101) -> 10.64 | D102: =AVERAGE(D2:D101) -> 8.03 | E102: =AVERAGE(E2:E101) -> 10.72 | F102: =AVERAGE(F2:F101) -> 38
A103: STDEV | B103: =STDEV(B2:B101) -> 4.7287964 | C103: =STDEV(C2:C101) -> 6.3285788 | D103: =STDEV(D2:D101) -> 4.8167532 | E103: =STDEV(E2:E101) -> 5.1797586 | F103: =STDEV(F2:F101) -> 0

Sheet Quoted Spend
A1: Iteration | B1: Tuberías ABC, S.A. de C.V. | C1: Tuberías DEF, S. de R.L. | D1: Tuberías GHI, S.A.S. | E1: Tuberías Súper, S.A.P.I. | F1: Total
A2: 1 | B2: =SUMIFS('Raw data'!$AC$2:$AC$3801,'Raw data'!$A$2:$A$3801,'Quoted Spend'!$A2,'Raw data'!$M$2:$M$3801,'Quoted Spend'!B$1) -> 64900.43 | C2: =SUMIFS('Raw data'!$AC$2:$AC$3801,'Raw data'!$A$2:$A$3801,'Quoted Spend'!$A2,'Raw data'!$M$2:$M$3801,'Quoted Spend'!C$1) -> 101125.84 | D2: =SUMIFS('Raw data'!$AC$2:$AC$3801,'Raw data'!$A$2:$A$3801,'Quoted Spend'!$A2,'Raw data'!$M$2:$M$3801,'Quoted Spend'!D$1) -> 75086.54 | E2: =SUMIFS('Raw data'!$AC$2:$AC$3801,'Raw data'!$A$2:$A$3801,'Quoted Spend'!$A2,'Raw data'!$M$2:$M$3801,'Quoted Spend'!E$1) -> 113564.31 | F2: =AVERAGE(B2:E2) -> 88669.28
A3: =A2+1 -> 2 | B3: =SUMIFS('Raw data'!$AC$2:$AC$3801,'Raw data'!$A$2:$A$3801,'Quoted Spend'!$A3,'Raw data'!$M$2:$M$3801,'Quoted Spend'!B$1) -> 182264.7 | C3: =SUMIFS('Raw data'!$AC$2:$AC$3801,'Raw data'!$A$2:$A$3801,'Quoted Spend'!$A3,'Raw data'!$M$2:$M$3801,'Quoted Spend'!C$1) -> 24060.86 | D3: =SUMIFS('Raw data'!$AC$2:$AC$3801,'Raw data'!$A$2:$A$3801,'Quoted Spend'!$A3,'Raw data'!$M$2:$M$3801,'Quoted Spend'!D$1) -> 26239.99 | E3: =SUMIFS('Raw data'!$AC$2:$AC$3801,'Raw data'!$A$2:$A$3801,'Quoted Spend'!$A3,'Raw data'!$M$2:$M$3801,'Quoted Spend'!E$1) -> 180249.06 | F3: =AVERAGE(B3:E3) -> 103203.65
A4: =A3+1 -> 3 | B4: =SUMIFS('Raw data'!$AC$2:$AC$3801,'Raw data'!$A$2:$A$3801,'Quoted Spend'!$A4,'Raw data'!$M$2:$M$3801,'Quoted Spend'!B$1) -> 98255.86 | C4: =SUMIFS('Raw data'!$AC$2:$AC$3801,'Raw data'!$A$2:$A$3801,'Quoted Spend'!$A4,'Raw data'!$M$2:$M$3801,'Quoted Spend'!C$1) -> 67248.64 | D4: =SUMIFS('Raw data'!$AC$2:$AC$3801,'Raw data'!$A$2:$A$3801,'Quoted Spend'!$A4,'Raw data'!$M$2:$M$3801,'Quoted Spend'!D$1) -> 116864.22 | E4: =SUMIFS('Raw data'!$AC$2:$AC$3801,'Raw data'!$A$2:$A$3801,'Quoted Spend'!$A4,'Raw data'!$M$2:$M$3801,'Quoted Spend'!E$1) -> 54342.98 | F4: =AVERAGE(B4:E4) -> 84177.925
A5: =A4+1 -> 4 | B5: =SUMIFS('Raw data'!$AC$2:$AC$3801,'Raw data'!$A$2:$A$3801,'Quoted Spend'!$A5,'Raw data'!$M$2:$M$3801,'Quoted Spend'!B$1) -> 27097.66 | C5: =SUMIFS('Raw data'!$AC$2:$AC$3801,'Raw data'!$A$2:$A$3801,'Quoted Spend'!$A5,'Raw data'!$M$2:$M$3801,'Quoted Spend'!C$1) -> 121985.26 | D5: =SUMIFS('Raw data'!$AC$2:$AC$3801,'Raw data'!$A$2:$A$3801,'Quoted Spend'!$A5,'Raw data'!$M$2:$M$3801,'Quoted Spend'!D$1) -> 41096.84 | E5: =SUMIFS('Raw data'!$AC$2:$AC$3801,'Raw data'!$A$2:$A$3801,'Quoted Spend'!$A5,'Raw data'!$M$2:$M$3801,'Quoted Spend'!E$1) -> 161223.3 | F5: =AVERAGE(B5:E5) -> 87850.765
A6: =A5+1 -> 5 | B6: =SUMIFS('Raw data'!$AC$2:$AC$3801,'Raw data'!$A$2:$A$3801,'Quoted Spend'!$A6,'Raw data'!$M$2:$M$3801,'Quoted Spend'!B$1) -> 124941.26 | C6: =SUMIFS('Raw data'!$AC$2:$AC$3801,'Raw data'!$A$2:$A$3801,'Quoted Spend'!$A6,'Raw data'!$M$2:$M$3801,'Quoted Spend'!C$1) -> 148811.66 | D6: =SUMIFS('Raw data'!$AC$2:$AC$3801,'Raw data'!$A$2:$A$3801,'Quoted Spend'!$A6,'Raw data'!$M$2:$M$3801,'Quoted Spend'!D$1) -> 57903.28 | E6: =SUMIFS('Raw data'!$AC$2:$AC$3801,'Raw data'!$A$2:$A$3801,'Quoted Spend'!$A6,'Raw data'!$M$2:$M$3801,'Quoted Spend'!E$1) -> 21830.86 | F6: =AVERAGE(B6:E6) -> 88371.765
A7: =A6+1 -> 6 | B7: =SUMIFS('Raw data'!$AC$2:$AC$3801,'Raw data'!$A$2:$A$3801,'Quoted Spend'!$A7,'Raw data'!$M$2:$M$3801,'Quoted Spend'!B$1) -> 45866.84 | C7: =SUMIFS('Raw data'!$AC$2:$AC$3801,'Raw data'!$A$2:$A$3801,'Quoted Spend'!$A7,'Raw data'!$M$2:$M$3801,'Quoted Spend'!C$1) -> 242783.75 | D7: =SUMIFS('Raw data'!$AC$2:$AC$3801,'Raw data'!$A$2:$A$3801,'Quoted Spend'!$A7,'Raw data'!$M$2:$M$3801,'Quoted Spend'!D$1) -> 0 | E7: =SUMIFS('Raw data'!$AC$2:$AC$3801,'Raw data'!$A$2:$A$3801,'Quoted Spend'!$A7,'Raw data'!$M$2:$M$3801,'Quoted Spend'!E$1) -> 111643.94 | F7: =AVERAGE(B7:E7) -> 100073.63
A8: =A7+1 -> 7 | B8: =SUMIFS('Raw data'!$AC$2:$AC$3801,'Raw data'!$A$2:$A$3801,'Quoted Spend'!$A8,'Raw data'!$M$2:$M$3801,'Quoted Spend'!B$1) -> 3871.36 | C8: =SUMIFS('Raw data'!$AC$2:$AC$3801,'Raw data'!$A$2:$A$3801,'Quoted Spend'!$A8,'Raw data'!$M$2:$M$3801,'Quoted Spend'!C$1) -> 61932.78 | D8: =SUMIFS('Raw data'!$AC$2:$AC$3801,'Raw data'!$A$2:$A$3801,'Quoted Spend'!$A8,'Raw data'!$M$2:$M$3801,'Quoted Spend'!D$1) -> 156461.96 | E8: =SUMIFS('Raw data'!$AC$2:$AC$3801,'Raw data'!$A$2:$A$3801,'Quoted Spend'!$A8,'Raw data'!$M$2:$M$3801,'Quoted Spend'!E$1) -> 122944.8 | F8: =AVERAGE(B8:E8) -> 86302.725
A9: =A8+1 -> 8 | B9: =SUMIFS('Raw data'!$AC$2:$AC$3801,'Raw data'!$A$2:$A$3801,'Quoted Spend'!$A9,'Raw data'!$M$2:$M$3801,'Quoted Spend'!B$1) -> 1740.41 | C9: =SUMIFS('Raw data'!$AC$2:$AC$3801,'Raw data'!$A$2:$A$3801,'Quoted Spend'!$A9,'Raw data'!$M$2:$M$3801,'Quoted Spend'!C$1) -> 244577.41 | D9: =SUMIFS('Raw data'!$AC$2:$AC$3801,'Raw data'!$A$2:$A$3801,'Quoted Spend'!$A9,'Raw data'!$M$2:$M$3801,'Quoted Spend'!D$1) -> 1700.85 | E9: =SUMIFS('Raw data'!$AC$2:$AC$3801,'Raw data'!$A$2:$A$3801,'Quoted Spend'!$A9,'Raw data'!$M$2:$M$3801,'Quoted Spend'!E$1) -> 143598.06 | F9: =AVERAGE(B9:E9) -> 97904.182
A10: =A9+1 -> 9 | B10: =SUMIFS('Raw data'!$AC$2:$AC$3801,'Raw data'!$A$2:$A$3801,'Quoted Spend'!$A10,'Raw data'!$M$2:$M$3801,'Quoted Spend'!B$1) -> 53492.35 | C10: =SUMIFS('Raw data'!$AC$2:$AC$3801,'Raw data'!$A$2:$A$3801,'Quoted Spend'!$A10,'Raw data'!$M$2:$M$3801,'Quoted Spend'!C$1) -> 119765.11 | D10: =SUMIFS('Raw data'!$AC$2:$AC$3801,'Raw data'!$A$2:$A$3801,'Quoted Spend'!$A10,'Raw data'!$M$2:$M$3801,'Quoted Spend'!D$1) -> 93912.49 | E10: =SUMIFS('Raw data'!$AC$2:$AC$3801,'Raw data'!$A$2:$A$3801,'Quoted Spend'!$A10,'Raw data'!$M$2:$M$3801,'Quoted Spend'!E$1) -> 136062.4 | F10: =AVERAGE(B10:E10) -> 100808.09
A11: =A10+1 -> 10 | B11: =SUMIFS('Raw data'!$AC$2:$AC$3801,'Raw data'!$A$2:$A$3801,'Quoted Spend'!$A11,'Raw data'!$M$2:$M$3801,'Quoted Spend'!B$1) -> 34614.44 | C11: =SUMIFS('Raw data'!$AC$2:$AC$3801,'Raw data'!$A$2:$A$3801,'Quoted Spend'!$A11,'Raw data'!$M$2:$M$3801,'Quoted Spend'!C$1) -> 104847.97 | D11: =SUMIFS('Raw data'!$AC$2:$AC$3801,'Raw data'!$A$2:$A$3801,'Quoted Spend'!$A11,'Raw data'!$M$2:$M$3801,'Quoted Spend'!D$1) -> 255765.17 | E11: =SUMIFS('Raw data'!$AC$2:$AC$3801,'Raw data'!$A$2:$A$3801,'Quoted Spend'!$A11,'Raw data'!$M$2:$M$3801,'Quoted Spend'!E$1) -> 20663.96 | F11: =AVERAGE(B11:E11) -> 103972.88
A12: =A11+1 -> 11 | B12: =SUMIFS('Raw data'!$AC$2:$AC$3801,'Raw data'!$A$2:$A$3801,'Quoted Spend'!$A12,'Raw data'!$M$2:$M$3801,'Quoted Spend'!B$1) -> 198868.57 | C12: =SUMIFS('Raw data'!$AC$2:$AC$3801,'Raw data'!$A$2:$A$3801,'Quoted Spend'!$A12,'Raw data'!$M$2:$M$3801,'Quoted Spend'!C$1) -> 49061.45 | D12: =SUMIFS('Raw data'!$AC$2:$AC$3801,'Raw data'!$A$2:$A$3801,'Quoted Spend'!$A12,'Raw data'!$M$2:$M$3801,'Quoted Spend'!D$1) -> 150869.77 | E12: =SUMIFS('Raw data'!$AC$2:$AC$3801,'Raw data'!$A$2:$A$3801,'Quoted Spend'!$A12,'Raw data'!$M$2:$M$3801,'Quoted Spend'!E$1) -> 940.24 | F12: =AVERAGE(B12:E12) -> 99935.007
A13: =A12+1 -> 12 | B13: =SUMIFS('Raw data'!$AC$2:$AC$3801,'Raw data'!$A$2:$A$3801,'Quoted Spend'!$A13,'Raw data'!$M$2:$M$3801,'Quoted Spend'!B$1) -> 17247.17 | C13: =SUMIFS('Raw data'!$AC$2:$AC$3801,'Raw data'!$A$2:$A$3801,'Quoted Spend'!$A13,'Raw data'!$M$2:$M$3801,'Quoted Spend'!C$1) -> 71739.1 | D13: =SUMIFS('Raw data'!$AC$2:$AC$3801,'Raw data'!$A$2:$A$3801,'Quoted Spend'!$A13,'Raw data'!$M$2:$M$3801,'Quoted Spend'!D$1) -> 113442.58 | E13: =SUMIFS('Raw data'!$AC$2:$AC$3801,'Raw data'!$A$2:$A$3801,'Quoted Spend'!$A13,'Raw data'!$M$2:$M$3801,'Quoted Spend'!E$1) -> 199728.82 | F13: =AVERAGE(B13:E13) -> 100539.42
A14: =A13+1 -> 13 | B14: =SUMIFS('Raw data'!$AC$2:$AC$3801,'Raw data'!$A$2:$A$3801,'Quoted Spend'!$A14,'Raw data'!$M$2:$M$3801,'Quoted Spend'!B$1) -> 77277 | C14: =SUMIFS('Raw data'!$AC$2:$AC$3801,'Raw data'!$A$2:$A$3801,'Quoted Spend'!$A14,'Raw data'!$M$2:$M$3801,'Quoted Spend'!C$1) -> 221552.23 | D14: =SUMIFS('Raw data'!$AC$2:$AC$3801,'Raw data'!$A$2:$A$3801,'Quoted Spend'!$A14,'Raw data'!$M$2:$M$3801,'Quoted Spend'!D$1) -> 34936.84 | E14: =SUMIFS('Raw data'!$AC$2:$AC$3801,'Raw data'!$A$2:$A$3801,'Quoted Spend'!$A14,'Raw data'!$M$2:$M$3801,'Quoted Spend'!E$1) -> 0 | F14: =AVERAGE(B14:E14) -> 83441.517
... A101: =A100+1 -> 100 | B101: =SUMIFS('Raw data'!$AC$2:$AC$3801,'Raw data'!$A$2:$A$3801,'Quoted Spend'!$A101,'Raw data'!$M$2:$M$3801,'Quoted Spend'!B$1) -> 150002.91 | C101: =SUMIFS('Raw data'!$AC$2:$AC$3801,'Raw data'!$A$2:$A$3801,'Quoted Spend'!$A101,'Raw data'!$M$2:$M$3801,'Quoted Spend'!C$1) -> 779.47 | D101: =SUMIFS('Raw data'!$AC$2:$AC$3801,'Raw data'!$A$2:$A$3801,'Quoted Spend'!$A101,'Raw data'!$M$2:$M$3801,'Quoted Spend'!D$1) -> 193788.78 | E101: =SUMIFS('Raw data'!$AC$2:$AC$3801,'Raw data'!$A$2:$A$3801,'Quoted Spend'!$A101,'Raw data'!$M$2:$M$3801,'Quoted Spend'!E$1) -> 76407.07 | F101: =AVERAGE(B101:E101) -> 105244.56
A102: AVG | B102: =AVERAGE(B2:B101) -> 85722.632 | C102: =AVERAGE(C2:C101) -> 105925.32 | D102: =AVERAGE(D2:D101) -> 75346.428 | E102: =AVERAGE(E2:E101) -> 105071.67 | F102: =AVERAGE(F2:F101) -> 93016.513 | G102: =AVERAGE(B2:E101) -> 93016.513
A103: STDEV | B103: =STDEV(B2:B101) -> 75083.687 | C103: =STDEV(C2:C101) -> 85251.33 | D103: =STDEV(D2:D101) -> 66952.782 | E103: =STDEV(E2:E101) -> 68431.966 | F103: =STDEV(F2:F101) -> 9002.0929 | G103: =STDEV(B2:E101) -> 75140.046
