Workbook

Sheet Raw data
A1: Iteration | B1: ECN | C1: Supplier ID | D1: New supplier | E1: Rule 1 | F1: Rule 2 | G1: Rule 3 | H1: Rule 4 | I1: Rule 5 | J1: Rule 6 | K1: Rule 7 | L1: Rule 8 | M1: Rule 9 | N1: Rule 10 | O1: Rule 11 | P1: Rule 12 | Q1: Rule 13 | R1: Rule 14 | S1: Rule 15 | T1: Rule 16 | U1: Rule 17 | V1: Rule 18 | W1: Score | X1: Wait | Y1: Implement | Z1: Action
A2: 1 | B2: ECN0000302 | C2: 10000082 | D2: TRUE | F2: 0 | G2: 0 | H2: 0 | I2: 0 | J2: 1 | W2: 3.1666667 | X2: 1 | Y2: 0 | Z2: Wait
A3: 1 | B3: ECN0000302 | C3: 10000073 | D3: TRUE | E3: 0 | F3: 0 | G3: 0 | H3: 0 | I3: 0.56863917 | J3: 0.25379741 | W3: 5.7864079 | X3: 0.25379741 | Y3: 0.56863917 | Z3: Implement
A4: 1 | B4: ECN0000305 | C4: 10000082 | D4: TRUE | F4: 0 | G4: 0 | H4: 0 | I4: 0 | J4: 0.93953983 | W4: 3.1666667 | X4: 1 | Y4: 0 | Z4: Wait
A5: 1 | B5: ECN0000305 | C5: 10000033 | D5: FALSE | E5: 0 | F5: 0 | G5: 0 | H5: 0 | I5: 0 | J5: 0 | K5: 0 | L5: 0 | M5: 0 | N5: 0 | O5: 0 | P5: 0.29659822 | Q5: 0 | R5: 0.10226786 | S5: 0 | T5: 0.10226786 | U5: 0 | V5: 0.70340178 | W5: 6.3805774 | X5: 0.10226786 | Y5: 0.70340178 | Z5: Implement
A6: 1 | B6: ECN0000301 | C6: 10000082 | D6: TRUE | F6: 0 | G6: 0 | H6: 0 | I6: 0 | J6: 1 | W6: 3.1666667 | X6: 1 | Y6: 0 | Z6: Wait
A7: 1 | B7: ECN0000301 | C7: 10000073 | D7: FALSE | E7: 0 | F7: 0 | G7: 0 | H7: 0 | I7: 0 | J7: 0 | K7: 0 | L7: 0 | M7: 0 | N7: 0 | O7: 0.42351265 | P7: 0 | Q7: 0.25867142 | R7: 0 | S7: 0.25867142 | T7: 0 | U7: 0.57648735 | V7: 0 | W7: 5.7846402 | X7: 0.25867142 | Y7: 0.57648735 | Z7: Implement
A8: 1 | B8: ECN0000304 | C8: 10000033 | D8: FALSE | E8: 0 | F8: 0 | G8: 0 | H8: 0 | I8: 0 | J8: 0 | K8: 0 | L8: 0 | M8: 0 | N8: 0 | O8: 0 | P8: 0.2995766 | Q8: 0 | R8: 0.11606382 | S8: 0 | T8: 0.11606382 | U8: 0 | V8: 0.7004234 | W8: 6.3393958 | X8: 0.11606382 | Y8: 0.7004234 | Z8: Implement
A9: 1 | B9: ECN0000306 | C9: 10000073 | D9: FALSE | E9: 0 | F9: 0 | G9: 0 | H9: 0 | I9: 0 | J9: 0 | K9: 0 | L9: 0 | M9: 0 | N9: 0 | O9: 0.42616333 | P9: 0 | Q9: 0.27785732 | R9: 0 | S9: 0.27785732 | T9: 0 | U9: 0.57383667 | V9: 0 | W9: 5.7260568 | X9: 0.27785732 | Y9: 0.57383667 | Z9: Implement
A10: 1 | B10: ECN0000303 | C10: 10000082 | D10: TRUE | F10: 0 | G10: 0 | H10: 0 | I10: 0 | J10: 0.99541878 | W10: 3.1666667 | X10: 1 | Y10: 0 | Z10: Wait
A11: 1 | B11: ECN0000308 | C11: 10000033 | D11: FALSE | E11: 0 | F11: 0 | G11: 0 | H11: 0 | I11: 0 | J11: 0 | K11: 0 | L11: 0 | M11: 0 | N11: 0 | O11: 0 | P11: 0.30536343 | Q11: 0 | R11: 0.13682097 | S11: 0 | T11: 0.13682097 | U11: 0 | V11: 0.69463657 | W11: 6.2762003 | X11: 0.13682097 | Y11: 0.69463657 | Z11: Implement
A12: 1 | B12: ECN0000303 | C12: 10000073 | D12: FALSE | E12: 0 | F12: 0 | G12: 0 | H12: 0 | I12: 0 | J12: 0 | K12: 0 | L12: 0 | M12: 0 | N12: 0 | O12: 0.42858598 | P12: 0 | Q12: 0.28023535 | R12: 0 | S12: 0.28023535 | T12: 0 | U12: 0.57141402 | V12: 0 | W12: 5.7154444 | X12: 0.28023535 | Y12: 0.57141402 | Z12: Implement
A13: 1 | B13: ECN0000309 | C13: 10000033 | D13: FALSE | E13: 0 | F13: 0 | G13: 0 | H13: 0 | I13: 0 | J13: 0 | K13: 0 | L13: 0 | M13: 0 | N13: 0 | O13: 0 | P13: 0.31427303 | Q13: 0 | R13: 0.13682097 | S13: 0 | T13: 0.13682097 | U13: 0 | V13: 0.68572697 | W13: 6.2674263 | X13: 0.13682097 | Y13: 0.68572697 | Z13: Implement
A14: 1 | B14: ECN0000307 | C14: 10000033 | D14: FALSE | E14: 0 | F14: 0 | G14: 0 | H14: 0.26666667 | I14: 0 | J14: 0.26666667 | K14: 0 | L14: 0.66753639 | M14: 0.1764358 | N14: 0 | O14: 0 | P14: 0 | Q14: 0 | R14: 0 | S14: 0 | T14: 0 | U14: 0 | V14: 0 | W14: 6.1376513 | X14: 0.1764358 | Y14: 0.66753639 | Z14: Implement
A15: 1 | B15: ECN0000310 | C15: 10000082 | D15: TRUE | F15: 0 | G15: 0.99435065 | H15: 0 | I15: 0 | J15: 0 | W15: 4.9954152 | X15: 1 | Y15: 0.99435065 | Z15: Wait
A16: 1 | B16: ECN0000310 | C16: 10000033 | D16: FALSE | E16: 0 | F16: 0 | G16: 0 | H16: 0.66253444 | I16: 0 | J16: 0.33746556 | K16: 0 | L16: 0 | M16: 0 | N16: 0 | O16: 0 | P16: 0 | Q16: 0 | R16: 0 | S16: 0 | T16: 0 | U16: 0 | V16: 0 | W16: 6.6494668 | X16: 0 | Y16: 0.66253444 | Z16: Implement
A17: 2 | B17: ECN0000310 | C17: 10000082 | D17: TRUE | F17: 0 | G17: 0 | H17: 0 | I17: 0.26014482 | J17: 0.73985518 | W17: 3.7375473 | X17: 1 | Y17: 0.26014482 | Z17: Wait
A18: 2 | B18: ECN0000310 | C18: 10000073 | D18: TRUE | E18: 0 | F18: 0 | G18: 0 | H18: 0 | I18: 0.56863917 | J18: 0.24632898 | W18: 5.8080504 | X18: 0.24632898 | Y18: 0.56863917 | Z18: Implement
A19: 2 | B19: ECN0000307 | C19: 10000047 | D19: FALSE | E19: 0 | F19: 0 | G19: 0 | H19: 0 | I19: 0 | J19: 0 | K19: 0 | L19: 0 | M19: 0 | N19: 0 | O19: 0.75784 | P19: 0 | Q19: 0.24216 | R19: 0 | S19: 0 | T19: 0 | U19: 0 | V19: 0 | W19: 6.0669176 | X19: 0.24216 | Y19: 0.75784 | Z19: Implement
A20: 2 | B20: ECN0000305 | C20: 10000073 | D20: FALSE | E20: 0 | F20: 0 | G20: 0 | H20: 0 | I20: 0 | J20: 0 | K20: 0 | L20: 0 | M20: 0 | N20: 0 | O20: 0.44676321 | P20: 0.32201488 | Q20: 0 | R20: 0 | S20: 0 | T20: 0 | U20: 0 | V20: 0.55323679 | W20: 6.5865783 | X20: 0 | Y20: 0.55323679 | Z20: Implement
A21: 2 | B21: ECN0000306 | C21: 10000082 | D21: TRUE | F21: 0 | G21: 0 | H21: 0 | I21: 1 | J21: 0 | W21: 5.0025004 | X21: 1 | Y21: 1 | Z21: Wait
A22: 2 | B22: ECN0000306 | C22: 10000033 | D22: FALSE | E22: 0 | F22: 0 | G22: 0 | H22: 0 | I22: 0 | J22: 0 | K22: 0 | L22: 0 | M22: 0 | N22: 0 | O22: 0 | P22: 0.30873154 | Q22: 0 | R22: 0.18176678 | S22: 0 | T22: 0.18176678 | U22: 0 | V22: 0.69126846 | W22: 6.1493598 | X22: 0.18176678 | Y22: 0.69126846 | Z22: Implement
A23: 2 | B23: ECN0000308 | C23: 10000082 | D23: TRUE | F23: 0 | G23: 0 | H23: 0 | I23: 1 | J23: 0 | W23: 5.0025004 | X23: 1 | Y23: 1 | Z23: Wait
A24: 2 | B24: ECN0000308 | C24: 10000073 | D24: FALSE | E24: 0 | F24: 0 | G24: 0 | H24: 0 | I24: 0 | J24: 0 | K24: 0 | L24: 0 | M24: 0 | N24: 0 | O24: 0.4322883 | P24: 0 | Q24: 0.37129742 | R24: 0 | S24: 0.28571429 | T24: 0 | U24: 0.28571429 | V24: 0.5677117 | W24: 5.4627858 | X24: 0.37129742 | Y24: 0.5677117 | Z24: Implement
A25: 2 | B25: ECN0000309 | C25: 10000082 | D25: TRUE | F25: 0 | G25: 0 | H25: 0 | I25: 1 | J25: 0 | W25: 5.0025004 | X25: 1 | Y25: 1 | Z25: Wait
A26: 2 | B26: ECN0000309 | C26: 10000047 | D26: FALSE | E26: 0 | F26: 0 | G26: 0 | H26: 0 | I26: 0 | J26: 0 | K26: 0 | L26: 0 | M26: 0 | N26: 0 | O26: 0.66548928 | P26: 0.18181818 | Q26: 0.33451072 | R26: 0 | S26: 0 | T26: 0 | U26: 0 | V26: 0 | W26: 5.7173382 | X26: 0.33451072 | Y26: 0.66548928 | Z26: Implement
A27: 2 | B27: ECN0000301 | C27: 10000033 | D27: FALSE | E27: 0 | F27: 0 | G27: 0 | H27: 0 | I27: 0 | J27: 0 | K27: 0 | L27: 0.43333333 | M27: 0.27296265 | N27: 0 | O27: 0 | P27: 0.33153928 | Q27: 0 | R27: 0.27296265 | S27: 0 | T27: 0.27296265 | U27: 0 | V27: 0.56666667 | W27: 5.7283192 | X27: 0.27296265 | Y27: 0.56666667 | Z27: Implement
A28: 2 | B28: ECN0000303 | C28: 10000082 | D28: TRUE | F28: 0 | G28: 0.78947923 | H28: 0 | I28: 0 | J28: 0 | W28: 4.7111012 | X28: 1 | Y28: 0.78947923 | Z28: Wait
A29: 2 | B29: ECN0000302 | C29: 10000073 | D29: FALSE | E29: 0.23333333 | F29: 0 | G29: 0.23333333 | H29: 0 | I29: 0 | J29: 0 | K29: 0.54994802 | L29: 0 | M29: 0 | N29: 0 | O29: 0 | P29: 0 | Q29: 0 | R29: 0 | S29: 0 | T29: 0 | U29: 0 | V29: 0 | W29: 3.41784 | X29: 0.54994802 | Y29: 0 | Z29: Wait
A30: 2 | B30: ECN0000303 | C30: 10000073 | D30: FALSE | E30: 0.4 | F30: 0 | G30: 0.4 | H30: 0 | I30: 0 | J30: 0 | K30: 0.54994802 | L30: 0 | M30: 0 | N30: 0 | O30: 0 | P30: 0 | Q30: 0 | R30: 0 | S30: 0 | T30: 0 | U30: 0 | V30: 0 | W30: 3.41784 | X30: 0.54994802 | Y30: 0 | Z30: Wait
A31: 2 | B31: ECN0000303 | C31: 10000033 | D31: FALSE | E31: 0 | F31: 0 | G31: 0 | H31: 0.5 | I31: 0 | J31: 0.32766287 | K31: 0 | L31: 0.5 | M31: 0.38418043 | N31: 0 | O31: 0 | P31: 0 | Q31: 0 | R31: 0 | S31: 0 | T31: 0 | U31: 0 | V31: 0 | W31: 5.2938289 | X31: 0.38418043 | Y31: 0.5 | Z31: Implement
A32: 2 | B32: ECN0000302 | C32: 10000082 | D32: TRUE | F32: 0 | G32: 0.6 | H32: 0 | I32: 0 | J32: 0 | W32: 4.4004238 | X32: 1 | Y32: 0.6 | Z32: Wait
A33: 2 | B33: ECN0000302 | C33: 10000033 | D33: FALSE | E33: 0 | F33: 0.32785365 | G33: 0.67214635 | H33: 0.25 | I33: 0.32785365 | J33: 0.25 | K33: 0 | L33: 0.16666667 | M33: 0.16666667 | N33: 0 | O33: 0 | P33: 0 | Q33: 0 | R33: 0 | S33: 0 | T33: 0 | U33: 0 | V33: 0 | W33: 4.2607058 | X33: 0.67214635 | Y33: 0.32785365 | Z33: Wait
A34: 2 | B34: ECN0000302 | C34: 10000047 | D34: FALSE | E34: 0.28571429 | F34: 0 | G34: 0 | H34: 0 | I34: 0.56546373 | J34: 0 | K34: 0 | L34: 0 | M34: 0 | N34: 0 | O34: 0 | P34: 0 | Q34: 0 | R34: 0 | S34: 0 | T34: 0 | U34: 0 | V34: 0 | W34: 5.6902479 | X34: 0.28571429 | Y34: 0.56546373 | Z34: Implement
A35: 2 | B35: ECN0000304 | C35: 10000047 | D35: FALSE | E35: 1 | F35: 0 | G35: 0 | H35: 0 | I35: 0 | J35: 0 | K35: 0 | L35: 0 | M35: 0 | N35: 0 | O35: 0 | P35: 0 | Q35: 0 | R35: 0 | S35: 0 | T35: 0 | U35: 0 | V35: 0 | W35: 3.1666667 | X35: 1 | Y35: 0 | Z35: Wait
A36: 2 | B36: ECN0000304 | C36: 10000033 | D36: FALSE | E36: 0 | F36: 0.35920161 | G36: 0.64079839 | H36: 0.25 | I36: 0.35920161 | J36: 0.25 | K36: 0 | L36: 0 | M36: 0 | N36: 0 | O36: 0 | P36: 0 | Q36: 0 | R36: 0 | S36: 0 | T36: 0 | U36: 0 | V36: 0 | W36: 4.3863865 | X36: 0.64079839 | Y36: 0.35920161 | Z36: Wait
A37: 2 | B37: ECN0000304 | C37: 10000082 | D37: TRUE | F37: 0 | G37: 0.99835495 | H37: 0 | I37: 0 | J37: 0 | W37: 5.0004414 | X37: 1 | Y37: 0.99835495 | Z37: Wait
A38: 2 | B38: ECN0000304 | C38: 10000073 | D38: FALSE | E38: 0.48245385 | F38: 0 | G38: 0.51754615 | H38: 0 | I38: 0 | J38: 0 | K38: 0 | L38: 0 | M38: 0 | N38: 0 | O38: 0 | P38: 0 | Q38: 0 | R38: 0 | S38: 0 | T38: 0 | U38: 0 | V38: 0 | W38: 3.4367084 | X38: 0.51754615 | Y38: 0 | Z38: Wait
A39: 3 | B39: ECN0000309 | C39: 10000033 | D39: FALSE | E39: 0 | F39: 0 | G39: 0 | H39: 0 | I39: 0 | J39: 0 | K39: 0 | L39: 0 | M39: 0 | N39: 0 | O39: 0 | P39: 0.30882978 | Q39: 0 | R39: 0.049191809 | S39: 0 | T39: 0.049191809 | U39: 0 | V39: 0.69117022 | W39: 6.5218776 | X39: 0.049191809 | Y39: 0.69117022 | Z39: Implement
A40: 3 | B40: ECN0000304 | C40: 10000082 | D40: TRUE | F40: 0 | G40: 0 | H40: 0 | I40: 0.50714947 | J40: 0.54200846 | W40: 4.2319173 | X40: 1 | Y40: 0.50714947 | Z40: Wait
...

Sheet Feuil1
A1: Iteración | B1: 10000033 | C1: 10000047 | D1: 10000073 | E1: 10000082 | F1: Total | H1: Iteración | I1: 10000033 | J1: 10000047 | K1: 10000073 | L1: 10000082
A2: 1 | B2: =IFERROR(AVERAGEIFS('Raw data'!$W$2:$W$1560,'Raw data'!$A$2:$A$1560,Feuil1!$A2,'Raw data'!$C$2:$C$1560,Feuil1!B$1),"") -> 6.3417863 | C2: =IFERROR(AVERAGEIFS('Raw data'!$W$2:$W$1560,'Raw data'!$A$2:$A$1560,Feuil1!$A2,'Raw data'!$C$2:$C$1560,Feuil1!C$1),"") | D2: =IFERROR(AVERAGEIFS('Raw data'!$W$2:$W$1560,'Raw data'!$A$2:$A$1560,Feuil1!$A2,'Raw data'!$C$2:$C$1560,Feuil1!D$1),"") -> 5.7531373 | E2: =IFERROR(AVERAGEIFS('Raw data'!$W$2:$W$1560,'Raw data'!$A$2:$A$1560,Feuil1!$A2,'Raw data'!$C$2:$C$1560,Feuil1!E$1),"") -> 3.5324164 | F2: =AVERAGE(B2:E2) -> 5.2091133 | H2: wait | I2: =COUNTIFS('Raw data'!$C:$C,Feuil1!I$1,'Raw data'!$Z:$Z,Feuil1!$H2) -> 46 | J2: =COUNTIFS('Raw data'!$C:$C,Feuil1!J$1,'Raw data'!$Z:$Z,Feuil1!$H2) -> 60 | K2: =COUNTIFS('Raw data'!$C:$C,Feuil1!K$1,'Raw data'!$Z:$Z,Feuil1!$H2) -> 68 | L2: =COUNTIFS('Raw data'!$C:$C,Feuil1!L$1,'Raw data'!$Z:$Z,Feuil1!$H2) -> 387
A3: 2 | B3: =IFERROR(AVERAGEIFS('Raw data'!$W$2:$W$1560,'Raw data'!$A$2:$A$1560,Feuil1!$A3,'Raw data'!$C$2:$C$1560,Feuil1!B$1),"") -> 5.1637201 | C3: =IFERROR(AVERAGEIFS('Raw data'!$W$2:$W$1560,'Raw data'!$A$2:$A$1560,Feuil1!$A3,'Raw data'!$C$2:$C$1560,Feuil1!C$1),"") -> 5.1602926 | D3: =IFERROR(AVERAGEIFS('Raw data'!$W$2:$W$1560,'Raw data'!$A$2:$A$1560,Feuil1!$A3,'Raw data'!$C$2:$C$1560,Feuil1!D$1),"") -> 4.6883005 | E3: =IFERROR(AVERAGEIFS('Raw data'!$W$2:$W$1560,'Raw data'!$A$2:$A$1560,Feuil1!$A3,'Raw data'!$C$2:$C$1560,Feuil1!E$1),"") -> 4.6938593 | F3: =AVERAGE(B3:E3) -> 4.9265431 | H3: implement | I3: =COUNTIFS('Raw data'!$C:$C,Feuil1!I$1,'Raw data'!$Z:$Z,Feuil1!$H3) -> 559 | J3: =COUNTIFS('Raw data'!$C:$C,Feuil1!J$1,'Raw data'!$Z:$Z,Feuil1!$H3) -> 237 | K3: =COUNTIFS('Raw data'!$C:$C,Feuil1!K$1,'Raw data'!$Z:$Z,Feuil1!$H3) -> 200 | L3: =COUNTIFS('Raw data'!$C:$C,Feuil1!L$1,'Raw data'!$Z:$Z,Feuil1!$H3) -> 2
A4: 3 | B4: =IFERROR(AVERAGEIFS('Raw data'!$W$2:$W$1560,'Raw data'!$A$2:$A$1560,Feuil1!$A4,'Raw data'!$C$2:$C$1560,Feuil1!B$1),"") -> 5.193223 | C4: =IFERROR(AVERAGEIFS('Raw data'!$W$2:$W$1560,'Raw data'!$A$2:$A$1560,Feuil1!$A4,'Raw data'!$C$2:$C$1560,Feuil1!C$1),"") -> 4.4337818 | D4: =IFERROR(AVERAGEIFS('Raw data'!$W$2:$W$1560,'Raw data'!$A$2:$A$1560,Feuil1!$A4,'Raw data'!$C$2:$C$1560,Feuil1!D$1),"") -> 5.6374521 | E4: =IFERROR(AVERAGEIFS('Raw data'!$W$2:$W$1560,'Raw data'!$A$2:$A$1560,Feuil1!$A4,'Raw data'!$C$2:$C$1560,Feuil1!E$1),"") -> 3.8321793 | F4: =AVERAGE(B4:E4) -> 4.774159
A5: 4 | B5: =IFERROR(AVERAGEIFS('Raw data'!$W$2:$W$1560,'Raw data'!$A$2:$A$1560,Feuil1!$A5,'Raw data'!$C$2:$C$1560,Feuil1!B$1),"") -> 5.8881674 | C5: =IFERROR(AVERAGEIFS('Raw data'!$W$2:$W$1560,'Raw data'!$A$2:$A$1560,Feuil1!$A5,'Raw data'!$C$2:$C$1560,Feuil1!C$1),"") -> 5.7995066 | D5: =IFERROR(AVERAGEIFS('Raw data'!$W$2:$W$1560,'Raw data'!$A$2:$A$1560,Feuil1!$A5,'Raw data'!$C$2:$C$1560,Feuil1!D$1),"") -> 5.7167576 | E5: =IFERROR(AVERAGEIFS('Raw data'!$W$2:$W$1560,'Raw data'!$A$2:$A$1560,Feuil1!$A5,'Raw data'!$C$2:$C$1560,Feuil1!E$1),"") -> 3.7516628 | F5: =AVERAGE(B5:E5) -> 5.2890236
A6: 5 | B6: =IFERROR(AVERAGEIFS('Raw data'!$W$2:$W$1560,'Raw data'!$A$2:$A$1560,Feuil1!$A6,'Raw data'!$C$2:$C$1560,Feuil1!B$1),"") -> 6.4762351 | C6: =IFERROR(AVERAGEIFS('Raw data'!$W$2:$W$1560,'Raw data'!$A$2:$A$1560,Feuil1!$A6,'Raw data'!$C$2:$C$1560,Feuil1!C$1),"") -> 5.5620402 | D6: =IFERROR(AVERAGEIFS('Raw data'!$W$2:$W$1560,'Raw data'!$A$2:$A$1560,Feuil1!$A6,'Raw data'!$C$2:$C$1560,Feuil1!D$1),"") -> 4.677634 | E6: =IFERROR(AVERAGEIFS('Raw data'!$W$2:$W$1560,'Raw data'!$A$2:$A$1560,Feuil1!$A6,'Raw data'!$C$2:$C$1560,Feuil1!E$1),"") -> 3.8818446 | F6: =AVERAGE(B6:E6) -> 5.1494385
A7: 6 | B7: =IFERROR(AVERAGEIFS('Raw data'!$W$2:$W$1560,'Raw data'!$A$2:$A$1560,Feuil1!$A7,'Raw data'!$C$2:$C$1560,Feuil1!B$1),"") -> 6.2538247 | C7: =IFERROR(AVERAGEIFS('Raw data'!$W$2:$W$1560,'Raw data'!$A$2:$A$1560,Feuil1!$A7,'Raw data'!$C$2:$C$1560,Feuil1!C$1),"") -> 6.2183775 | D7: =IFERROR(AVERAGEIFS('Raw data'!$W$2:$W$1560,'Raw data'!$A$2:$A$1560,Feuil1!$A7,'Raw data'!$C$2:$C$1560,Feuil1!D$1),"") -> 6.244278 | E7: =IFERROR(AVERAGEIFS('Raw data'!$W$2:$W$1560,'Raw data'!$A$2:$A$1560,Feuil1!$A7,'Raw data'!$C$2:$C$1560,Feuil1!E$1),"") -> 3.7008822 | F7: =AVERAGE(B7:E7) -> 5.6043406
A8: 7 | B8: =IFERROR(AVERAGEIFS('Raw data'!$W$2:$W$1560,'Raw data'!$A$2:$A$1560,Feuil1!$A8,'Raw data'!$C$2:$C$1560,Feuil1!B$1),"") -> 6.0919113 | C8: =IFERROR(AVERAGEIFS('Raw data'!$W$2:$W$1560,'Raw data'!$A$2:$A$1560,Feuil1!$A8,'Raw data'!$C$2:$C$1560,Feuil1!C$1),"") -> 5.7330738 | D8: =IFERROR(AVERAGEIFS('Raw data'!$W$2:$W$1560,'Raw data'!$A$2:$A$1560,Feuil1!$A8,'Raw data'!$C$2:$C$1560,Feuil1!D$1),"") -> 5.7234832 | E8: =IFERROR(AVERAGEIFS('Raw data'!$W$2:$W$1560,'Raw data'!$A$2:$A$1560,Feuil1!$A8,'Raw data'!$C$2:$C$1560,Feuil1!E$1),"") -> 4.7200922 | F8: =AVERAGE(B8:E8) -> 5.5671401
A9: 8 | B9: =IFERROR(AVERAGEIFS('Raw data'!$W$2:$W$1560,'Raw data'!$A$2:$A$1560,Feuil1!$A9,'Raw data'!$C$2:$C$1560,Feuil1!B$1),"") -> 5.5194174 | C9: =IFERROR(AVERAGEIFS('Raw data'!$W$2:$W$1560,'Raw data'!$A$2:$A$1560,Feuil1!$A9,'Raw data'!$C$2:$C$1560,Feuil1!C$1),"") -> 4.7182291 | D9: =IFERROR(AVERAGEIFS('Raw data'!$W$2:$W$1560,'Raw data'!$A$2:$A$1560,Feuil1!$A9,'Raw data'!$C$2:$C$1560,Feuil1!D$1),"") -> 5.1832422 | E9: =IFERROR(AVERAGEIFS('Raw data'!$W$2:$W$1560,'Raw data'!$A$2:$A$1560,Feuil1!$A9,'Raw data'!$C$2:$C$1560,Feuil1!E$1),"") -> 4.9570234 | F9: =AVERAGE(B9:E9) -> 5.094478
A10: 9 | B10: =IFERROR(AVERAGEIFS('Raw data'!$W$2:$W$1560,'Raw data'!$A$2:$A$1560,Feuil1!$A10,'Raw data'!$C$2:$C$1560,Feuil1!B$1),"") -> 5.9312037 | C10: =IFERROR(AVERAGEIFS('Raw data'!$W$2:$W$1560,'Raw data'!$A$2:$A$1560,Feuil1!$A10,'Raw data'!$C$2:$C$1560,Feuil1!C$1),"") -> 6.1054474 | D10: =IFERROR(AVERAGEIFS('Raw data'!$W$2:$W$1560,'Raw data'!$A$2:$A$1560,Feuil1!$A10,'Raw data'!$C$2:$C$1560,Feuil1!D$1),"") -> 4.3843474 | E10: =IFERROR(AVERAGEIFS('Raw data'!$W$2:$W$1560,'Raw data'!$A$2:$A$1560,Feuil1!$A10,'Raw data'!$C$2:$C$1560,Feuil1!E$1),"") -> 3.9336805 | F10: =AVERAGE(B10:E10) -> 5.0886698
A11: 10 | B11: =IFERROR(AVERAGEIFS('Raw data'!$W$2:$W$1560,'Raw data'!$A$2:$A$1560,Feuil1!$A11,'Raw data'!$C$2:$C$1560,Feuil1!B$1),"") -> 5.7696624 | C11: =IFERROR(AVERAGEIFS('Raw data'!$W$2:$W$1560,'Raw data'!$A$2:$A$1560,Feuil1!$A11,'Raw data'!$C$2:$C$1560,Feuil1!C$1),"") -> 5.1953211 | D11: =IFERROR(AVERAGEIFS('Raw data'!$W$2:$W$1560,'Raw data'!$A$2:$A$1560,Feuil1!$A11,'Raw data'!$C$2:$C$1560,Feuil1!D$1),"") -> 5.7302159 | E11: =IFERROR(AVERAGEIFS('Raw data'!$W$2:$W$1560,'Raw data'!$A$2:$A$1560,Feuil1!$A11,'Raw data'!$C$2:$C$1560,Feuil1!E$1),"") -> 3.8322645 | F11: =AVERAGE(B11:E11) -> 5.131866
A12: 11 | B12: =IFERROR(AVERAGEIFS('Raw data'!$W$2:$W$1560,'Raw data'!$A$2:$A$1560,Feuil1!$A12,'Raw data'!$C$2:$C$1560,Feuil1!B$1),"") -> 5.9628633 | C12: =IFERROR(AVERAGEIFS('Raw data'!$W$2:$W$1560,'Raw data'!$A$2:$A$1560,Feuil1!$A12,'Raw data'!$C$2:$C$1560,Feuil1!C$1),"") -> 5.7158814 | D12: =IFERROR(AVERAGEIFS('Raw data'!$W$2:$W$1560,'Raw data'!$A$2:$A$1560,Feuil1!$A12,'Raw data'!$C$2:$C$1560,Feuil1!D$1),"") -> 5.4018763 | E12: =IFERROR(AVERAGEIFS('Raw data'!$W$2:$W$1560,'Raw data'!$A$2:$A$1560,Feuil1!$A12,'Raw data'!$C$2:$C$1560,Feuil1!E$1),"") -> 4.1366786 | F12: =AVERAGE(B12:E12) -> 5.3043249
A13: 12 | B13: =IFERROR(AVERAGEIFS('Raw data'!$W$2:$W$1560,'Raw data'!$A$2:$A$1560,Feuil1!$A13,'Raw data'!$C$2:$C$1560,Feuil1!B$1),"") -> 5.142835 | C13: =IFERROR(AVERAGEIFS('Raw data'!$W$2:$W$1560,'Raw data'!$A$2:$A$1560,Feuil1!$A13,'Raw data'!$C$2:$C$1560,Feuil1!C$1),"") -> 5.1338677 | D13: =IFERROR(AVERAGEIFS('Raw data'!$W$2:$W$1560,'Raw data'!$A$2:$A$1560,Feuil1!$A13,'Raw data'!$C$2:$C$1560,Feuil1!D$1),"") -> 4.446712 | E13: =IFERROR(AVERAGEIFS('Raw data'!$W$2:$W$1560,'Raw data'!$A$2:$A$1560,Feuil1!$A13,'Raw data'!$C$2:$C$1560,Feuil1!E$1),"") -> 4.8816551 | F13: =AVERAGE(B13:E13) -> 4.9012674
A14: 13 | B14: =IFERROR(AVERAGEIFS('Raw data'!$W$2:$W$1560,'Raw data'!$A$2:$A$1560,Feuil1!$A14,'Raw data'!$C$2:$C$1560,Feuil1!B$1),"") -> 6.0243388 | C14: =IFERROR(AVERAGEIFS('Raw data'!$W$2:$W$1560,'Raw data'!$A$2:$A$1560,Feuil1!$A14,'Raw data'!$C$2:$C$1560,Feuil1!C$1),"") -> 6.007189 | D14: =IFERROR(AVERAGEIFS('Raw data'!$W$2:$W$1560,'Raw data'!$A$2:$A$1560,Feuil1!$A14,'Raw data'!$C$2:$C$1560,Feuil1!D$1),"") -> 5.6910822 | E14: =IFERROR(AVERAGEIFS('Raw data'!$W$2:$W$1560,'Raw data'!$A$2:$A$1560,Feuil1!$A14,'Raw data'!$C$2:$C$1560,Feuil1!E$1),"") -> 5.0015841 | F14: =AVERAGE(B14:E14) -> 5.6810485
A15: 14 | B15: =IFERROR(AVERAGEIFS('Raw data'!$W$2:$W$1560,'Raw data'!$A$2:$A$1560,Feuil1!$A15,'Raw data'!$C$2:$C$1560,Feuil1!B$1),"") -> 6.2374731 | C15: =IFERROR(AVERAGEIFS('Raw data'!$W$2:$W$1560,'Raw data'!$A$2:$A$1560,Feuil1!$A15,'Raw data'!$C$2:$C$1560,Feuil1!C$1),"") -> 6.3156286 | D15: =IFERROR(AVERAGEIFS('Raw data'!$W$2:$W$1560,'Raw data'!$A$2:$A$1560,Feuil1!$A15,'Raw data'!$C$2:$C$1560,Feuil1!D$1),"") -> 4.9569123 | E15: =IFERROR(AVERAGEIFS('Raw data'!$W$2:$W$1560,'Raw data'!$A$2:$A$1560,Feuil1!$A15,'Raw data'!$C$2:$C$1560,Feuil1!E$1),"") -> 4.5963302 | F15: =AVERAGE(B15:E15) -> 5.5265861
... A101: 100 | B101: =IFERROR(AVERAGEIFS('Raw data'!$W$2:$W$1560,'Raw data'!$A$2:$A$1560,Feuil1!$A101,'Raw data'!$C$2:$C$1560,Feuil1!B$1),"") -> 5.7425646 | C101: =IFERROR(AVERAGEIFS('Raw data'!$W$2:$W$1560,'Raw data'!$A$2:$A$1560,Feuil1!$A101,'Raw data'!$C$2:$C$1560,Feuil1!C$1),"") -> 5.3420354 | D101: =IFERROR(AVERAGEIFS('Raw data'!$W$2:$W$1560,'Raw data'!$A$2:$A$1560,Feuil1!$A101,'Raw data'!$C$2:$C$1560,Feuil1!D$1),"") -> 4.7844255 | E101: =IFERROR(AVERAGEIFS('Raw data'!$W$2:$W$1560,'Raw data'!$A$2:$A$1560,Feuil1!$A101,'Raw data'!$C$2:$C$1560,Feuil1!E$1),"") -> 3.2466446 | F101: =AVERAGE(B101:E101) -> 4.7789175
A102: Con AVG | B102: =AVERAGE(B2:B101) -> 5.9605441 | C102: =AVERAGE(C2:C101) -> 5.5471708 | D102: =AVERAGE(D2:D101) -> 5.2738081 | E102: =AVERAGE(E2:E101) -> 4.1630245 | F102: =AVERAGE(B2:E101) -> 5.236985
A103: Con STDV | B103: =STDEV(B2:B101) -> 0.36430021 | C103: =STDEV(C2:C101) -> 0.7034928 | D103: =STDEV(D2:D101) -> 0.60867453 | E103: =STDEV(E2:E101) -> 0.62806787 | F103: =STDEV(B2:E101) -> 0.89247986
A104: Ind AVG | B104: =AVERAGEIF(B2:B101,"<>""",B2:B101) -> 5.9605441 | C104: =AVERAGEIF(C2:C101,"<>""",C2:C101) -> 5.5471708 | D104: =AVERAGEIF(D2:D101,"<>""",D2:D101) -> 5.2738081 | E104: =AVERAGEIF(E2:E101,"<>""",E2:E101) -> 4.1630245 | F104: =AVERAGEIF(B4:E103,"<>""",B4:E103) -> 5.1922268
A105: Ind STDV | B105: {=STDEV(_xlfn._xlws.FILTER(B2:B101,B2:B101<>""))} -> 0.36430021 | C105: {=STDEV(_xlfn._xlws.FILTER(C2:C101,C2:C101<>""))} -> 0.7034928 | D105: {=STDEV(_xlfn._xlws.FILTER(D2:D101,D2:D101<>""))} -> 0.60867453 | E105: {=STDEV(_xlfn._xlws.FILTER(E2:E101,E2:E101<>""))} -> 0.62806787 | F105: {=STDEV(_xlfn.VSTACK(_xlfn._xlws.FILTER(B2:B101,B2:B101<>""),_xlfn._xlws.FILTER(C2:C101,B2:B101<>""),_xlfn._xlws.FILTER(D2:D101,B2:B101<>""),_xlfn._xlws.FILTER(E2:E101,B2:B101<>"")))} -> 0.89247986
